Workbook

Sheet À lire
C1: Détecter les clients qui partent vers Wave Business
A2: FICTIF : clients, volumes et incidents inventés pour illustrer la méthode. Aucun nom, montant ni date ne vient de Julaya.
A4: Ce que fait ce tableau
A5: Le but | B5: Repérer chaque mois, à partir des volumes payés, les clients qui commencent à faire passer une partie de leurs paiements ailleurs, Wave Business en tête, avant qu'ils ne partent tout à fait.
A6: Le premier signe | B6: Un client qui teste Wave déplace d'abord ses paiements vers des portefeuilles Wave (salaires, journaliers), puis le reste. Une baisse des flux vers Wave alors que le volume total tient, c'est l'alerte la plus précoce.
A8: Les onglets
A9: Volumes mensuels | B9: L'export à coller chaque mois : un client par ligne, volume total payé, volume vers des portefeuilles Wave et nombre de bénéficiaires sur six mois, plus quelques informations de compte. C'est le seul onglet à remplir.
A10: Détection | B10: Se calcule seul : les trois baisses, le score de risque de 0 à 100, le niveau, le signal principal, l'action recommandée et le revenu annuel en jeu.
A11: Plan d'action | B11: Les comptes critiques et élevés du mois, avec la personne qui agit, la date limite, le premier message en brouillon et les colonnes de suivi.
A12: Synthèse | B12: Le nombre de comptes et le revenu en jeu par niveau, les signaux qui reviennent, la répartition par secteur.
A13: Paramètres | B13: Les seuils et les points du score. Les changer met tout le tableau à jour.
A15: Le score, en clair
A16: Baisse du volume total | B16: Moyenne juil.-sept. comparée à avr.-juin. 35 points si la baisse atteint 40%, 25 si 20 %, 12 si 10 %.
A17: Baisse des flux vers Wave | B17: Septembre comparé à la moyenne avr.-juin. 25 points dès 50 %, 15 dès 25 %.
A18: Jours sans lot de paiement | B18: 15 points au-delà de 21 jours, 8 au-delà de 10 jours.
A19: Autres signaux | B19: Bénéficiaires en baisse de 30 % ou plus : 10 points. Réclamation sur les 90 derniers jours : 10. Aucune intégration (ni API ni export comptable) : 5. Pas de contrat annuel : 5.
A20: Les niveaux | B20: Critique à partir de 60, élevé à partir de 40, à surveiller à partir de 20, sain en dessous. Un client marqué « activité saisonnière » ne dépasse pas « à surveiller » : sa baisse est attendue.
A21: Revenu annuel en jeu | B21: Volume mensuel moyen avr.-juin × taux de commission × 12. Le taux de 0.9% est une hypothèse fictive, à remplacer par le taux moyen réel de Julaya dans les Paramètres.
A23: Ce qui ne part jamais sans accord | B23: Tout message à un client avant validation ; toute remise, alignement tarifaire ou condition particulière, décidés par la direction de Julaya. Une condition accordée à un client ne se cite pas à un autre.

Sheet Synthèse
C1: Synthèse du mois
A2: FICTIF : clients, volumes et incidents inventés pour illustrer la méthode. Aucun nom, montant ni date ne vient de Julaya.
A3: Se calcule seule à partir de l'onglet Détection.
A5: Par niveau de risque
A6: Niveau | B6: Clients | C6: Revenu annuel en jeu | D6: Part du revenu | E6: Ce qu'on fait
A7: Critique | B7: =COUNTIF('Détection'!M6:M45,A7) | C7: =SUMIF('Détection'!M6:M45,A7,'Détection'!O6:O45) | D7: =C7/C11 | E7: Directeur commercial, sous 48 h
A8: Élevé | B8: =COUNTIF('Détection'!M6:M45,A8) | C8: =SUMIF('Détection'!M6:M45,A8,'Détection'!O6:O45) | D8: =C8/C11 | E8: Chargé de compte, sous 7 jours
A9: À surveiller | B9: =COUNTIF('Détection'!M6:M45,A9) | C9: =SUMIF('Détection'!M6:M45,A9,'Détection'!O6:O45) | D9: =C9/C11 | E9: Revu au prochain export
A10: Sain | B10: =COUNTIF('Détection'!M6:M45,A10) | C10: =SUMIF('Détection'!M6:M45,A10,'Détection'!O6:O45) | D10: =C10/C11 | E10: Rien ce mois-ci
A11: Total | B11: =SUM(B7:B10) | C11: =SUM(C7:C10)
A13: Revenu annuel en jeu sur les comptes critiques et élevés | C13: =C7+C8
A15: Signal principal (comptes non sains)
A16: Signal | B16: Clients | C16: Revenu annuel en jeu
A17: Départ en cours | B17: =COUNTIF('Détection'!N6:N45,A17) | C17: =SUMIF('Détection'!N6:N45,A17,'Détection'!O6:O45)
A18: Flux Wave qui partent | B18: =COUNTIF('Détection'!N6:N45,A18) | C18: =SUMIF('Détection'!N6:N45,A18,'Détection'!O6:O45)
A19: Incident non soldé | B19: =COUNTIF('Détection'!N6:N45,A19) | C19: =SUMIF('Détection'!N6:N45,A19,'Détection'!O6:O45)
A20: Baisse saisonnière probable | B20: =COUNTIF('Détection'!N6:N45,A20) | C20: =SUMIF('Détection'!N6:N45,A20,'Détection'!O6:O45)
A21: Baisse de volume | B21: =COUNTIF('Détection'!N6:N45,A21) | C21: =SUMIF('Détection'!N6:N45,A21,'Détection'!O6:O45)
A23: Par secteur
A24: Secteur | B24: Clients | C24: Dont critiques ou élevés | D24: Score moyen
A25: Agro-industrie | B25: =COUNTIF('Détection'!D6:D45,A25) | C25: =COUNTIFS('Détection'!D6:D45,A25,'Détection'!M6:M45,"Critique")+COUNTIFS('Détection'!D6:D45,A25,'Détection'!M6:M45,"Élevé") | D25: =ROUND(AVERAGEIF('Détection'!D6:D45,A25,'Détection'!L6:L45),0)
A26: Assurance | B26: =COUNTIF('Détection'!D6:D45,A26) | C26: =COUNTIFS('Détection'!D6:D45,A26,'Détection'!M6:M45,"Critique")+COUNTIFS('Détection'!D6:D45,A26,'Détection'!M6:M45,"Élevé") | D26: =ROUND(AVERAGEIF('Détection'!D6:D45,A26,'Détection'!L6:L45),0)
A27: BTP | B27: =COUNTIF('Détection'!D6:D45,A27) | C27: =COUNTIFS('Détection'!D6:D45,A27,'Détection'!M6:M45,"Critique")+COUNTIFS('Détection'!D6:D45,A27,'Détection'!M6:M45,"Élevé") | D27: =ROUND(AVERAGEIF('Détection'!D6:D45,A27,'Détection'!L6:L45),0)
A28: Distribution | B28: =COUNTIF('Détection'!D6:D45,A28) | C28: =COUNTIFS('Détection'!D6:D45,A28,'Détection'!M6:M45,"Critique")+COUNTIFS('Détection'!D6:D45,A28,'Détection'!M6:M45,"Élevé") | D28: =ROUND(AVERAGEIF('Détection'!D6:D45,A28,'Détection'!L6:L45),0)
A29: Hôtellerie | B29: =COUNTIF('Détection'!D6:D45,A29) | C29: =COUNTIFS('Détection'!D6:D45,A29,'Détection'!M6:M45,"Critique")+COUNTIFS('Détection'!D6:D45,A29,'Détection'!M6:M45,"Élevé") | D29: =ROUND(AVERAGEIF('Détection'!D6:D45,A29,'Détection'!L6:L45),0)
A30: Immobilier | B30: =COUNTIF('Détection'!D6:D45,A30) | C30: =COUNTIFS('Détection'!D6:D45,A30,'Détection'!M6:M45,"Critique")+COUNTIFS('Détection'!D6:D45,A30,'Détection'!M6:M45,"Élevé") | D30: =ROUND(AVERAGEIF('Détection'!D6:D45,A30,'Détection'!L6:L45),0)
A31: Industrie | B31: =COUNTIF('Détection'!D6:D45,A31) | C31: =COUNTIFS('Détection'!D6:D45,A31,'Détection'!M6:M45,"Critique")+COUNTIFS('Détection'!D6:D45,A31,'Détection'!M6:M45,"Élevé") | D31: =ROUND(AVERAGEIF('Détection'!D6:D45,A31,'Détection'!L6:L45),0)
A32: Microfinance | B32: =COUNTIF('Détection'!D6:D45,A32) | C32: =COUNTIFS('Détection'!D6:D45,A32,'Détection'!M6:M45,"Critique")+COUNTIFS('Détection'!D6:D45,A32,'Détection'!M6:M45,"Élevé") | D32: =ROUND(AVERAGEIF('Détection'!D6:D45,A32,'Détection'!L6:L45),0)
A33: ONG / bailleurs | B33: =COUNTIF('Détection'!D6:D45,A33) | C33: =COUNTIFS('Détection'!D6:D45,A33,'Détection'!M6:M45,"Critique")+COUNTIFS('Détection'!D6:D45,A33,'Détection'!M6:M45,"Élevé") | D33: =ROUND(AVERAGEIF('Détection'!D6:D45,A33,'Détection'!L6:L45),0)
A34: Restauration | B34: =COUNTIF('Détection'!D6:D45,A34) | C34: =COUNTIFS('Détection'!D6:D45,A34,'Détection'!M6:M45,"Critique")+COUNTIFS('Détection'!D6:D45,A34,'Détection'!M6:M45,"Élevé") | D34: =ROUND(AVERAGEIF('Détection'!D6:D45,A34,'Détection'!L6:L45),0)
A35: Santé | B35: =COUNTIF('Détection'!D6:D45,A35) | C35: =COUNTIFS('Détection'!D6:D45,A35,'Détection'!M6:M45,"Critique")+COUNTIFS('Détection'!D6:D45,A35,'Détection'!M6:M45,"Élevé") | D35: =ROUND(AVERAGEIF('Détection'!D6:D45,A35,'Détection'!L6:L45),0)
A36: Services aux entreprises | B36: =COUNTIF('Détection'!D6:D45,A36) | C36: =COUNTIFS('Détection'!D6:D45,A36,'Détection'!M6:M45,"Critique")+COUNTIFS('Détection'!D6:D45,A36,'Détection'!M6:M45,"Élevé") | D36: =ROUND(AVERAGEIF('Détection'!D6:D45,A36,'Détection'!L6:L45),0)
A37: Sécurité privée | B37: =COUNTIF('Détection'!D6:D45,A37) | C37: =COUNTIFS('Détection'!D6:D45,A37,'Détection'!M6:M45,"Critique")+COUNTIFS('Détection'!D6:D45,A37,'Détection'!M6:M45,"Élevé") | D37: =ROUND(AVERAGEIF('Détection'!D6:D45,A37,'Détection'!L6:L45),0)
A38: Technologie | B38: =COUNTIF('Détection'!D6:D45,A38) | C38: =COUNTIFS('Détection'!D6:D45,A38,'Détection'!M6:M45,"Critique")+COUNTIFS('Détection'!D6:D45,A38,'Détection'!M6:M45,"Élevé") | D38: =ROUND(AVERAGEIF('Détection'!D6:D45,A38,'Détection'!L6:L45),0)
A39: Transport / logistique | B39: =COUNTIF('Détection'!D6:D45,A39) | C39: =COUNTIFS('Détection'!D6:D45,A39,'Détection'!M6:M45,"Critique")+COUNTIFS('Détection'!D6:D45,A39,'Détection'!M6:M45,"Élevé") | D39: =ROUND(AVERAGEIF('Détection'!D6:D45,A39,'Détection'!L6:L45),0)
A40: Télécoms / services | B40: =COUNTIF('Détection'!D6:D45,A40) | C40: =COUNTIFS('Détection'!D6:D45,A40,'Détection'!M6:M45,"Critique")+COUNTIFS('Détection'!D6:D45,A40,'Détection'!M6:M45,"Élevé") | D40: =ROUND(AVERAGEIF('Détection'!D6:D45,A40,'Détection'!L6:L45),0)
A41: Éducation | B41: =COUNTIF('Détection'!D6:D45,A41) | C41: =COUNTIFS('Détection'!D6:D45,A41,'Détection'!M6:M45,"Critique")+COUNTIFS('Détection'!D6:D45,A41,'Détection'!M6:M45,"Élevé") | D41: =ROUND(AVERAGEIF('Détection'!D6:D45,A41,'Détection'!L6:L45),0)
A42: Énergie | B42: =COUNTIF('Détection'!D6:D45,A42) | C42: =COUNTIFS('Détection'!D6:D45,A42,'Détection'!M6:M45,"Critique")+COUNTIFS('Détection'!D6:D45,A42,'Détection'!M6:M45,"Élevé") | D42: =ROUND(AVERAGEIF('Détection'!D6:D45,A42,'Détection'!L6:L45),0)
A43: Événementiel | B43: =COUNTIF('Détection'!D6:D45,A43) | C43: =COUNTIFS('Détection'!D6:D45,A43,'Détection'!M6:M45,"Critique")+COUNTIFS('Détection'!D6:D45,A43,'Détection'!M6:M45,"Élevé") | D43: =ROUND(AVERAGEIF('Détection'!D6:D45,A43,'Détection'!L6:L45),0)
A45: Lecture : quand un même signal touche plus d'un client sur cinq, c'est un sujet d'offre ou de prix à porter à la direction de Julaya, que la relance ne réglera pas.

Sheet Paramètres
C1: Paramètres du score
A2: FICTIF : clients, volumes et incidents inventés pour illustrer la méthode. Aucun nom, montant ni date ne vient de Julaya.
A3: Cases bleues : modifiables. Tout le tableau se recalcule.
A5: Date de l'export | B5: 46316
A6: Taux de commission moyen de Julaya | B6: 0.009 | C6: FICTIF : à remplacer par le taux réel
A7: Baisse du volume total : seuil fort | B7: 0.4
A8: points | B8: 35
A9: Baisse du volume total : seuil moyen | B9: 0.2
A10: points | B10: 25
A11: Baisse du volume total : seuil faible | B11: 0.1
A12: points | B12: 12
A13: Baisse des flux vers Wave : seuil fort | B13: 0.5 | C13: Septembre comparé à la moyenne avr.-juin
A14: points | B14: 25
A15: Baisse des flux vers Wave : seuil moyen | B15: 0.25
A16: points | B16: 15
A17: Jours sans lot : seuil long | B17: 21
A18: points | B18: 15
A19: Jours sans lot : seuil court | B19: 10
A20: points | B20: 8
A21: Baisse des bénéficiaires : seuil | B21: 0.3
A22: points | B22: 10
A23: Réclamation sur 90 jours : points | B23: 10
A24: Aucune intégration : points | B24: 5
A25: Pas de contrat annuel : points | B25: 5
... A28: Niveau « À surveiller » à partir de | B28: 20
A31: Action recommandée selon le signal principal
A32: Signal | B32: Action
A33: Départ en cours | B33: Appel du directeur commercial sous 48 h. Comprendre la raison, dans les mots du client, avant toute offre.
A34: Flux Wave qui partent | B34: Revue de compte sous 7 jours : montrer le coût réel d'un éclatement des paiements (double validation, rapprochement, exports). Option ⟦alignement sur les seuls flux Wave, à décider par la direction⟧.
A35: Incident non soldé | B35: Solder l'incident d'abord (appel du chargé de compte, cause et correctif), aucune offre commerciale avant.
A36: Baisse saisonnière probable | B36: Vérifier avec le client que la baisse est bien saisonnière. Pas d'action commerciale.
A37: Baisse de volume | B37: Point de compte par le chargé de compte dans le mois : ce qui a changé chez le client.
A38: — | B38: Rien à faire ce mois-ci.

Sheet Volumes mensuels
C1: Volumes mensuels payés par client (export à coller chaque mois)
A2: FICTIF : clients, volumes et incidents inventés pour illustrer la méthode. Aucun nom, montant ni date ne vient de Julaya.
A3: Montants en FCFA. Une ligne par client. Seul onglet à remplir.
A5: ID | B5: Client | C5: Secteur | D5: Pays | E5: Chargé de compte | F5: Intégration | G5: Contrat | H5: Activité saisonnière | I5: Réclamation (90 j) | J5: Jours depuis le dernier lot | K5: Volume total avr. | L5: Volume total mai | M5: Volume total juin | N5: Volume total juil. | O5: Volume total août | P5: Volume total sept. | Q5: Vers Wave avr. | R5: Vers Wave mai | S5: Vers Wave juin | T5: Vers Wave juil. | U5: Vers Wave août | V5: Vers Wave sept. | W5: Bénéficiaires avr. | X5: Bénéficiaires mai | Y5: Bénéficiaires juin | Z5: Bénéficiaires juil. | AA5: Bénéficiaires août | AB5: Bénéficiaires sept.
A6: JUL-101 | B6: Sotradis Négoce | C6: Distribution | D6: CI | E6: Aïcha K. | F6: Export compta | G6: Sans engagement | H6: Non | I6: Frais jugés trop élevés | J6: 10 | K6: 299600000 | L6: 314200000 | M6: 301200000 | N6: 287600000 | O6: 248100000 | P6: 212100000 | Q6: 113900000 | R6: 119400000 | S6: 114500000 | T6: 85000000 | U6: 53000000 | V6: 33600000 | W6: 425 | X6: 419 | Y6: 427 | Z6: 387 | AA6: 351 | AB6: 333
A7: JUL-102 | B7: Bâtirama BTP | C7: BTP | D7: CI | E7: Serge T. | F7: Aucune | G7: Sans engagement | H7: Non | I7: Lot de salaires en échec | J7: 37 | K7: 278200000 | L7: 274900000 | M7: 240000000 | N7: 185500000 | O7: 124600000 | P7: 76800000 | Q7: 83500000 | R7: 82500000 | S7: 68200000 | T7: 47700000 | U7: 29100000 | V7: 15400000 | W7: 659 | X7: 655 | Y7: 611 | Z7: 445 | AA7: 322 | AB7: 232
A8: JUL-103 | B8: Agrivoire Coop | C8: Agro-industrie | D8: CI | E8: Mariam D. | F8: Export compta | G8: Annuel | H8: Oui | J8: 11 | K8: 239600000 | L8: 228900000 | M8: 222000000 | N8: 139800000 | O8: 137200000 | P8: 209400000 | Q8: 52700000 | R8: 50400000 | S8: 48800000 | T8: 30800000 | U8: 30200000 | V8: 46100000 | W8: 1177 | X8: 1226 | Y8: 1220 | Z8: 864 | AA8: 792 | AB8: 1085
A9: JUL-104 | B9: ONG Sahel Espoir | C9: ONG / bailleurs | D9: SN | E9: Yannick B. | F9: API | G9: Annuel | H9: Non | J9: 5 | K9: 94100000 | L9: 97800000 | M9: 106700000 | N9: 100000000 | O9: 110700000 | P9: 111600000 | Q9: 42400000 | R9: 42500000 | S9: 44900000 | T9: 40700000 | U9: 43700000 | V9: 42700000 | W9: 179 | X9: 182 | Y9: 186 | Z9: 186 | AA9: 200 | AB9: 198
A10: JUL-105 | B10: Kodjo Logistique | C10: Transport / logistique | D10: TG | E10: Aïcha K. | F10: Aucune | G10: Sans engagement | H10: Non | J10: 15 | K10: 137900000 | L10: 137900000 | M10: 137300000 | N10: 120500000 | O10: 115100000 | P10: 102600000 | Q10: 56500000 | R10: 56500000 | S10: 56300000 | T10: 38400000 | U10: 26500000 | V10: 17500000 | W10: 318 | X10: 312 | Y10: 303 | Z10: 291 | AA10: 262 | AB10: 251
A11: JUL-106 | B11: Clinique Les Palmes | C11: Santé | D11: CI | E11: Serge T. | F11: Export compta | G11: Annuel | H11: Non | J11: 3 | K11: 63000000 | L11: 60400000 | M11: 61600000 | N11: 63500000 | O11: 60700000 | P11: 63000000 | Q11: 22100000 | R11: 21100000 | S11: 21600000 | T11: 22200000 | U11: 21200000 | V11: 22000000 | W11: 144 | X11: 141 | Y11: 139 | Z11: 136 | AA11: 143 | AB11: 136
A12: JUL-107 | B12: Garde Sûre Sécurité | C12: Sécurité privée | D12: CI | E12: Mariam D. | F12: Aucune | G12: Sans engagement | H12: Non | J12: 16 | K12: 189200000 | L12: 178300000 | M12: 192600000 | N12: 174000000 | O12: 146000000 | P12: 131500000 | Q12: 98400000 | R12: 92700000 | S12: 100200000 | T12: 70400000 | U12: 42700000 | V12: 28500000 | W12: 876 | X12: 908 | Y12: 899 | Z12: 848 | AA12: 749 | AB12: 732
A13: JUL-108 | B13: Groupe scolaire Lumière | C13: Éducation | D13: CI | E13: Yannick B. | F13: Aucune | G13: Sans engagement | H13: Oui | J13: 11 | K13: 39000000 | L13: 38700000 | M13: 34400000 | N13: 23100000 | O13: 21100000 | P13: 32000000 | Q13: 18700000 | R13: 18600000 | S13: 16500000 | T13: 11100000 | U13: 10100000 | V13: 15400000 | W13: 92 | X13: 98 | Y13: 96 | Z13: 68 | AA13: 61 | AB13: 88
A14: JUL-109 | B14: Ivoire Minoterie | C14: Agro-industrie | D14: CI | E14: Aïcha K. | F14: API | G14: Annuel | H14: Non | J14: 6 | K14: 218800000 | L14: 236100000 | M14: 226600000 | N14: 238800000 | O14: 243800000 | P14: 250300000 | Q14: 54700000 | R14: 57000000 | S14: 52900000 | T14: 54000000 | U14: 53500000 | V14: 53300000 | W14: 372 | X14: 391 | Y14: 396 | Z14: 403 | AA14: 402 | AB14: 415
A15: JUL-110 | B15: Dakar Fret Services | C15: Transport / logistique | D15: SN | E15: Serge T. | F15: Export compta | G15: Sans engagement | H15: Non | I15: Lot de salaires en échec | J15: 10 | K15: 123200000 | L15: 122500000 | M15: 122400000 | N15: 114500000 | O15: 108300000 | P15: 96400000 | Q15: 40600000 | R15: 40400000 | S15: 40400000 | T15: 37800000 | U15: 35000000 | V15: 30300000 | W15: 255 | X15: 256 | Y15: 257 | Z15: 258 | AA15: 253 | AB15: 234
A16: JUL-111 | B16: Cotonou Distribution | C16: Distribution | D16: BJ | E16: Mariam D. | F16: Export compta | G16: Annuel | H16: Non | J16: 6 | K16: 111400000 | L16: 106600000 | M16: 108100000 | N16: 105200000 | O16: 109100000 | P16: 111700000 | Q16: 32300000 | R16: 30900000 | S16: 31300000 | T16: 30500000 | U16: 31600000 | V16: 32400000 | W16: 213 | X16: 211 | Y16: 206 | Z16: 212 | AA16: 215 | AB16: 212
A17: JUL-112 | B17: Hôtel Lagune Bleue | C17: Hôtellerie | D17: CI | E17: Yannick B. | F17: Aucune | G17: Sans engagement | H17: Non | J17: 9 | K17: 45900000 | L17: 48800000 | M17: 46900000 | N17: 42800000 | O17: 39500000 | P17: 34000000 | Q17: 20200000 | R17: 21500000 | S17: 20600000 | T17: 14600000 | U17: 9800000 | V17: 6200000 | W17: 155 | X17: 156 | Y17: 161 | Z17: 147 | AA17: 135 | AB17: 126
A18: JUL-113 | B18: Projet Eau Pour Tous | C18: ONG / bailleurs | D18: BJ | E18: Aïcha K. | F18: Export compta | G18: Annuel | H18: Non | J18: 5 | K18: 57100000 | L18: 57600000 | M18: 59800000 | N18: 62000000 | O18: 61100000 | P18: 63900000 | Q18: 22900000 | R18: 22300000 | S18: 22400000 | T18: 22400000 | U18: 21400000 | V18: 21700000 | W18: 76 | X18: 78 | Y18: 80 | Z18: 80 | AA18: 83 | AB18: 83
A19: JUL-114 | B19: Sahel Telecom Services | C19: Télécoms / services | D19: SN | E19: Serge T. | F19: API | G19: Annuel | H19: Non | J19: 6 | K19: 168800000 | L19: 173500000 | M19: 195600000 | N19: 192600000 | O19: 208600000 | P19: 199600000 | Q19: 60800000 | R19: 60400000 | S19: 65800000 | T19: 62800000 | U19: 65900000 | V19: 61100000 | W19: 341 | X19: 343 | Y19: 359 | Z19: 352 | AA19: 372 | AB19: 370
A20: JUL-115 | B20: Bouaké Agro Plus | C20: Agro-industrie | D20: CI | E20: Mariam D. | F20: Aucune | G20: Sans engagement | H20: Non | I20: Lot de salaires en échec | J20: 31 | K20: 135800000 | L20: 135200000 | M20: 120300000 | N20: 93000000 | O20: 57900000 | P20: 38800000 | Q20: 42100000 | R20: 41900000 | S20: 35300000 | T20: 24700000 | U20: 14000000 | V20: 8000000 | W20: 535 | X20: 520 | Y20: 500 | Z20: 357 | AA20: 258 | AB20: 184
A21: JUL-116 | B21: Résidences Akwaba | C21: Immobilier | D21: CI | E21: Yannick B. | F21: Export compta | G21: Sans engagement | H21: Non | J21: 3 | K21: 74200000 | L21: 73500000 | M21: 72000000 | N21: 72800000 | O21: 70100000 | P21: 72300000 | Q21: 14800000 | R21: 14700000 | S21: 14400000 | T21: 14600000 | U21: 14000000 | V21: 14500000 | W21: 62 | X21: 58 | Y21: 58 | Z21: 61 | AA21: 58 | AB21: 59
A22: JUL-117 | B22: Nettoyage Pro Abidjan | C22: Services aux entreprises | D22: CI | E22: Aïcha K. | F22: Aucune | G22: Sans engagement | H22: Non | J22: 10 | K22: 100900000 | L22: 98300000 | M22: 94900000 | N22: 88700000 | O22: 80800000 | P22: 73600000 | Q22: 57500000 | R22: 56000000 | S22: 54100000 | T22: 39300000 | U22: 25900000 | V22: 17500000 | W22: 489 | X22: 467 | Y22: 477 | Z22: 434 | AA22: 416 | AB22: 393
A23: JUL-118 | B23: Lomé Port Manutention | C23: Transport / logistique | D23: TG | E23: Serge T. | F23: API | G23: Annuel | H23: Non | J23: 1 | K23: 197900000 | L23: 212700000 | M23: 219200000 | N23: 230500000 | O23: 225600000 | P23: 244200000 | Q23: 67300000 | R23: 69900000 | S23: 69600000 | T23: 70900000 | U23: 67300000 | V23: 70700000 | W23: 700 | X23: 716 | Y23: 736 | Z23: 727 | AA23: 746 | AB23: 747
A24: JUL-119 | B24: Pharmadis Afrique | C24: Santé | D24: CI | E24: Mariam D. | F24: API | G24: Annuel | H24: Non | J24: 5 | K24: 142900000 | L24: 151400000 | M24: 159600000 | N24: 152700000 | O24: 163000000 | P24: 165200000 | Q24: 25700000 | R24: 26300000 | S24: 26900000 | T24: 24900000 | U24: 25700000 | V24: 25300000 | W24: 118 | X24: 121 | Y24: 124 | Z24: 125 | AA24: 128 | AB24: 130
A25: JUL-120 | B25: Restaurants Gbaka & Co | C25: Restauration | D25: CI | E25: Yannick B. | F25: Aucune | G25: Sans engagement | H25: Non | I25: Lot de salaires en échec | J25: 32 | K25: 40400000 | L25: 41500000 | M25: 39800000 | N25: 27700000 | O25: 19000000 | P25: 12500000 | Q25: 22200000 | R25: 22800000 | S25: 20700000 | T25: 13100000 | U25: 8100000 | V25: 4600000 | W25: 230 | X25: 226 | Y25: 218 | Z25: 164 | AA25: 118 | AB25: 79
A26: JUL-121 | B26: Fondation Avenir Jeunes | C26: ONG / bailleurs | D26: CI | E26: Aïcha K. | F26: Aucune | G26: Annuel | H26: Non | I26: Lot de salaires en échec | J26: 7 | K26: 32300000 | L26: 34400000 | M26: 34900000 | N26: 32800000 | O26: 31400000 | P26: 27100000 | Q26: 13600000 | R26: 14400000 | S26: 14600000 | T26: 13800000 | U26: 12900000 | V26: 10800000 | W26: 50 | X26: 50 | Y26: 50 | Z26: 51 | AA26: 49 | AB26: 46
A27: JUL-122 | B27: Énergie Solaire Nord | C27: Énergie | D27: CI | E27: Serge T. | F27: Export compta | G27: Annuel | H27: Non | J27: 6 | K27: 86700000 | L27: 91200000 | M27: 92300000 | N27: 92000000 | O27: 92300000 | P27: 90100000 | Q27: 23400000 | R27: 24600000 | S27: 24900000 | T27: 24800000 | U27: 24900000 | V27: 24300000 | W27: 152 | X27: 151 | Y27: 154 | Z27: 152 | AA27: 152 | AB27: 147
A28: JUL-123 | B28: Thiès Industries | C28: Industrie | D28: SN | E28: Mariam D. | F28: Export compta | G28: Annuel | H28: Non | J28: 3 | K28: 161800000 | L28: 165500000 | M28: 166300000 | N28: 182600000 | O28: 182000000 | P28: 194700000 | Q28: 38800000 | R28: 38400000 | S28: 37300000 | T28: 39700000 | U28: 38300000 | V28: 39800000 | W28: 389 | X28: 390 | Y28: 398 | Z28: 407 | AA28: 410 | AB28: 421
A29: JUL-124 | B29: Marché Frais Cocody | C29: Distribution | D29: CI | E29: Yannick B. | F29: Aucune | G29: Sans engagement | H29: Non | J29: 11 | K29: 50100000 | L29: 53400000 | M29: 50900000 | N29: 46600000 | O29: 43100000 | P29: 38400000 | Q29: 25100000 | R29: 26700000 | S29: 25500000 | T29: 18100000 | U29: 12100000 | V29: 8000000 | W29: 107 | X29: 112 | Y29: 112 | Z29: 101 | AA29: 94 | AB29: 89
A30: JUL-125 | B30: Assurances Kpêkpê | C30: Assurance | D30: CI | E30: Aïcha K. | F30: API | G30: Annuel | H30: Non | J30: 1 | K30: 233000000 | L30: 242600000 | M30: 252300000 | N30: 247800000 | O30: 269900000 | P30: 262100000 | Q30: 34900000 | R30: 35200000 | S30: 35400000 | T30: 33600000 | U30: 35500000 | V30: 33500000 | W30: 86 | X30: 89 | Y30: 88 | Z30: 92 | AA30: 94 | AB30: 95
A31: JUL-126 | B31: Yamoussoukro Matériaux | C31: BTP | D31: CI | E31: Serge T. | F31: Export compta | G31: Sans engagement | H31: Non | I31: Délai de virement bancaire | J31: 6 | K31: 96100000 | L31: 95100000 | M31: 97600000 | N31: 90600000 | O31: 91100000 | P31: 74100000 | Q31: 31700000 | R31: 31400000 | S31: 32200000 | T31: 29900000 | U31: 29400000 | V31: 23300000 | W31: 262 | X31: 254 | Y31: 260 | Z31: 266 | AA31: 247 | AB31: 239
A32: JUL-127 | B32: Microcrédit Solidaire | C32: Microfinance | D32: BJ | E32: Mariam D. | F32: API | G32: Annuel | H32: Non | J32: 7 | K32: 119000000 | L32: 126200000 | M32: 125000000 | N32: 123400000 | O32: 126700000 | P32: 123100000 | Q32: 45200000 | R32: 47900000 | S32: 47500000 | T32: 46900000 | U32: 48100000 | V32: 46800000 | W32: 142 | X32: 140 | Y32: 144 | Z32: 141 | AA32: 139 | AB32: 142
A33: JUL-128 | B33: Abidjan Events | C33: Événementiel | D33: CI | E33: Yannick B. | F33: Aucune | G33: Sans engagement | H33: Oui | J33: 5 | K33: 30200000 | L33: 29800000 | M33: 28200000 | N33: 16800000 | O33: 15600000 | P33: 24200000 | Q33: 13900000 | R33: 13700000 | S33: 13000000 | T33: 7700000 | U33: 7200000 | V33: 11100000 | W33: 71 | X33: 72 | Y33: 69 | Z33: 48 | AA33: 46 | AB33: 65
A34: JUL-129 | B34: Transports Express Ouest | C34: Transport / logistique | D34: CI | E34: Aïcha K. | F34: Aucune | G34: Sans engagement | H34: Non | I34: Lot de salaires en échec | J34: 23 | K34: 78400000 | L34: 79100000 | M34: 71300000 | N34: 55700000 | O34: 33400000 | P34: 22700000 | Q34: 38400000 | R34: 38800000 | S34: 33100000 | T34: 23400000 | U34: 12700000 | V34: 7400000 | W34: 323 | X34: 333 | Y34: 306 | Z34: 227 | AA34: 168 | AB34: 116
A35: JUL-130 | B35: Cabinet Conseil Baobab | C35: Services aux entreprises | D35: SN | E35: Serge T. | F35: Export compta | G35: Annuel | H35: Non | J35: 6 | K35: 22800000 | L35: 22200000 | M35: 21800000 | N35: 22000000 | O35: 22300000 | P35: 21500000 | Q35: 6900000 | R35: 6700000 | S35: 6500000 | T35: 6600000 | U35: 6700000 | V35: 6400000 | W35: 45 | X35: 44 | Y35: 46 | Z35: 44 | AA35: 46 | AB35: 45
A36: JUL-131 | B36: San Pedro Cacao Export | C36: Agro-industrie | D36: CI | E36: Mariam D. | F36: API | G36: Annuel | H36: Non | J36: 6 | K36: 283200000 | L36: 293900000 | M36: 312900000 | N36: 330700000 | O36: 337900000 | P36: 337000000 | Q36: 65100000 | R36: 65300000 | S36: 67300000 | T36: 68800000 | U36: 68200000 | V36: 66000000 | W36: 820 | X36: 797 | Y36: 831 | Z36: 830 | AA36: 854 | AB36: 868
A37: JUL-132 | B37: Tech Hub Plateau | C37: Technologie | D37: CI | E37: Yannick B. | F37: API | G37: Sans engagement | H37: Non | J37: 2 | K37: 29800000 | L37: 31200000 | M37: 33900000 | N37: 34700000 | O37: 35100000 | P37: 34700000 | Q37: 11000000 | R37: 11100000 | S37: 11700000 | T37: 11600000 | U37: 11400000 | V37: 10900000 | W37: 67 | X37: 68 | Y37: 66 | Z37: 69 | AA37: 71 | AB37: 72
A38: JUL-133 | B38: Boulangeries Délices | C38: Restauration | D38: CI | E38: Aïcha K. | F38: Aucune | G38: Sans engagement | H38: Non | J38: 11 | K38: 37000000 | L38: 37700000 | M38: 35500000 | N38: 31400000 | O38: 29900000 | P38: 25600000 | Q38: 19600000 | R38: 20000000 | S38: 18800000 | T38: 12900000 | U38: 8900000 | V38: 5600000 | W38: 194 | X38: 187 | Y38: 194 | Z38: 177 | AA38: 158 | AB38: 149
A39: JUL-134 | B39: Projet Santé Rurale | C39: ONG / bailleurs | D39: TG | E39: Serge T. | F39: Export compta | G39: Annuel | H39: Non | J39: 1 | K39: 66800000 | L39: 73700000 | M39: 72000000 | N39: 73400000 | O39: 79800000 | P39: 81800000 | Q39: 26100000 | R39: 27800000 | S39: 26200000 | T39: 25900000 | U39: 27300000 | V39: 27200000 | W39: 119 | X39: 120 | Y39: 126 | Z39: 125 | AA39: 130 | AB39: 134
A40: JUL-135 | B40: Grands Moulins du Sud | C40: Industrie | D40: BJ | E40: Mariam D. | F40: Export compta | G40: Annuel | H40: Non | J40: 2 | K40: 131100000 | L40: 140400000 | M40: 140800000 | N40: 135300000 | O40: 137900000 | P40: 130500000 | Q40: 34100000 | R40: 36500000 | S40: 36600000 | T40: 35200000 | U40: 35800000 | V40: 33900000 | W40: 284 | X40: 288 | Y40: 295 | Z40: 282 | AA40: 294 | AB40: 283
A41: JUL-136 | B41: Auto Pièces Treichville | C41: Distribution | D41: CI | E41: Yannick B. | F41: Aucune | G41: Sans engagement | H41: Non | I41: Lot de salaires en échec | J41: 10 | K41: 27400000 | L41: 26400000 | M41: 28200000 | N41: 26400000 | O41: 24600000 | P41: 23000000 | Q41: 12900000 | R41: 12400000 | S41: 13300000 | T41: 12400000 | U41: 11300000 | V41: 10300000 | W41: 56 | X41: 56 | Y41: 55 | Z41: 53 | AA41: 53 | AB41: 49
...

Sheet Détection
C1: Détection des clients à risque
A2: FICTIF : clients, volumes et incidents inventés pour illustrer la méthode. Aucun nom, montant ni date ne vient de Julaya.
A3: Tout se calcule depuis l'onglet Volumes mensuels et les Paramètres. Triez sur la colonne Score.
A5: ID | B5: Client | C5: Chargé de compte | D5: Secteur | E5: Moyenne mensuelle avr.-juin | F5: Moyenne mensuelle juil.-sept. | G5: Baisse du volume total | H5: Baisse des flux vers Wave (sept.) | I5: Baisse des bénéficiaires (sept.) | J5: Jours sans lot | K5: Réclamation (90 j) | L5: Score de risque (0-100) | M5: Niveau | N5: Signal principal | O5: Revenu annuel en jeu | P5: Action recommandée
A6: ='Volumes mensuels'!A6 | B6: ='Volumes mensuels'!B6 | C6: ='Volumes mensuels'!E6 | D6: ='Volumes mensuels'!C6 | E6: =AVERAGE('Volumes mensuels'!K6:M6) | F6: =AVERAGE('Volumes mensuels'!N6:P6) | G6: =MAX(0,1-F6/E6) | H6: =IF(AVERAGE('Volumes mensuels'!Q6:S6)=0,0,MAX(0,1-'Volumes mensuels'!V6/AVERAGE('Volumes mensuels'!Q6:S6))) | I6: =MAX(0,1-'Volumes mensuels'!AB6/AVERAGE('Volumes mensuels'!W6:Y6)) | J6: ='Volumes mensuels'!J6 | K6: ='Volumes mensuels'!I6 | L6: =MIN(100,IF(G6>=Paramètres!$B$7,Paramètres!$B$8,IF(G6>=Paramètres!$B$9,Paramètres!$B$10,IF(G6>=Paramètres!$B$11,Paramètres!$B$12,0)))+IF(H6>=Paramètres!$B$13,Paramètres!$B$14,IF(H6>=Paramètres!$B$15,Paramètres!$B$16,0))+IF(J6>Paramètres!$B$17,Paramètres!$B$18,IF(J6>Paramètres!$B$19,Paramètres!$B$20,0))+IF(I6>=Paramètres!$B$21,Paramètres!$B$22,0)+IF(K6<>"",Paramètres!$B$23,0)+IF('Volumes mensuels'!F6="Aucune",Paramètres!$B$24,0)+IF('Volumes mensuels'!G6="Sans engagement",Paramètres!$B$25,0)) | M6: =IF(AND('Volumes mensuels'!H6="Oui",L6>=Paramètres!$B$27),"À surveiller",IF(L6>=Paramètres!$B$26,"Critique",IF(L6>=Paramètres!$B$27,"Élevé",IF(L6>=Paramètres!$B$28,"À surveiller","Sain")))) | N6: =IF(M6="Sain","—",IF(AND(J6>Paramètres!$B$17,G6>=Paramètres!$B$7),"Départ en cours",IF(H6>=Paramètres!$B$13,"Flux Wave qui partent",IF(K6<>"","Incident non soldé",IF('Volumes mensuels'!H6="Oui","Baisse saisonnière probable","Baisse de volume"))))) | O6: =ROUND(E6*Paramètres!$B$6*12,-3) | P6: =VLOOKUP(N6,Paramètres!$A$33:$B$38,2,FALSE)
A7: ='Volumes mensuels'!A7 | B7: ='Volumes mensuels'!B7 | C7: ='Volumes mensuels'!E7 | D7: ='Volumes mensuels'!C7 | E7: =AVERAGE('Volumes mensuels'!K7:M7) | F7: =AVERAGE('Volumes mensuels'!N7:P7) | G7: =MAX(0,1-F7/E7) | H7: =IF(AVERAGE('Volumes mensuels'!Q7:S7)=0,0,MAX(0,1-'Volumes mensuels'!V7/AVERAGE('Volumes mensuels'!Q7:S7))) | I7: =MAX(0,1-'Volumes mensuels'!AB7/AVERAGE('Volumes mensuels'!W7:Y7)) | J7: ='Volumes mensuels'!J7 | K7: ='Volumes mensuels'!I7 | L7: =MIN(100,IF(G7>=Paramètres!$B$7,Paramètres!$B$8,IF(G7>=Paramètres!$B$9,Paramètres!$B$10,IF(G7>=Paramètres!$B$11,Paramètres!$B$12,0)))+IF(H7>=Paramètres!$B$13,Paramètres!$B$14,IF(H7>=Paramètres!$B$15,Paramètres!$B$16,0))+IF(J7>Paramètres!$B$17,Paramètres!$B$18,IF(J7>Paramètres!$B$19,Paramètres!$B$20,0))+IF(I7>=Paramètres!$B$21,Paramètres!$B$22,0)+IF(K7<>"",Paramètres!$B$23,0)+IF('Volumes mensuels'!F7="Aucune",Paramètres!$B$24,0)+IF('Volumes mensuels'!G7="Sans engagement",Paramètres!$B$25,0)) | M7: =IF(AND('Volumes mensuels'!H7="Oui",L7>=Paramètres!$B$27),"À surveiller",IF(L7>=Paramètres!$B$26,"Critique",IF(L7>=Paramètres!$B$27,"Élevé",IF(L7>=Paramètres!$B$28,"À surveiller","Sain")))) | N7: =IF(M7="Sain","—",IF(AND(J7>Paramètres!$B$17,G7>=Paramètres!$B$7),"Départ en cours",IF(H7>=Paramètres!$B$13,"Flux Wave qui partent",IF(K7<>"","Incident non soldé",IF('Volumes mensuels'!H7="Oui","Baisse saisonnière probable","Baisse de volume"))))) | O7: =ROUND(E7*Paramètres!$B$6*12,-3) | P7: =VLOOKUP(N7,Paramètres!$A$33:$B$38,2,FALSE)
A8: ='Volumes mensuels'!A8 | B8: ='Volumes mensuels'!B8 | C8: ='Volumes mensuels'!E8 | D8: ='Volumes mensuels'!C8 | E8: =AVERAGE('Volumes mensuels'!K8:M8) | F8: =AVERAGE('Volumes mensuels'!N8:P8) | G8: =MAX(0,1-F8/E8) | H8: =IF(AVERAGE('Volumes mensuels'!Q8:S8)=0,0,MAX(0,1-'Volumes mensuels'!V8/AVERAGE('Volumes mensuels'!Q8:S8))) | I8: =MAX(0,1-'Volumes mensuels'!AB8/AVERAGE('Volumes mensuels'!W8:Y8)) | J8: ='Volumes mensuels'!J8 | K8: ='Volumes mensuels'!I8 | L8: =MIN(100,IF(G8>=Paramètres!$B$7,Paramètres!$B$8,IF(G8>=Paramètres!$B$9,Paramètres!$B$10,IF(G8>=Paramètres!$B$11,Paramètres!$B$12,0)))+IF(H8>=Paramètres!$B$13,Paramètres!$B$14,IF(H8>=Paramètres!$B$15,Paramètres!$B$16,0))+IF(J8>Paramètres!$B$17,Paramètres!$B$18,IF(J8>Paramètres!$B$19,Paramètres!$B$20,0))+IF(I8>=Paramètres!$B$21,Paramètres!$B$22,0)+IF(K8<>"",Paramètres!$B$23,0)+IF('Volumes mensuels'!F8="Aucune",Paramètres!$B$24,0)+IF('Volumes mensuels'!G8="Sans engagement",Paramètres!$B$25,0)) | M8: =IF(AND('Volumes mensuels'!H8="Oui",L8>=Paramètres!$B$27),"À surveiller",IF(L8>=Paramètres!$B$26,"Critique",IF(L8>=Paramètres!$B$27,"Élevé",IF(L8>=Paramètres!$B$28,"À surveiller","Sain")))) | N8: =IF(M8="Sain","—",IF(AND(J8>Paramètres!$B$17,G8>=Paramètres!$B$7),"Départ en cours",IF(H8>=Paramètres!$B$13,"Flux Wave qui partent",IF(K8<>"","Incident non soldé",IF('Volumes mensuels'!H8="Oui","Baisse saisonnière probable","Baisse de volume"))))) | O8: =ROUND(E8*Paramètres!$B$6*12,-3) | P8: =VLOOKUP(N8,Paramètres!$A$33:$B$38,2,FALSE)
A9: ='Volumes mensuels'!A9 | B9: ='Volumes mensuels'!B9 | C9: ='Volumes mensuels'!E9 | D9: ='Volumes mensuels'!C9 | E9: =AVERAGE('Volumes mensuels'!K9:M9) | F9: =AVERAGE('Volumes mensuels'!N9:P9) | G9: =MAX(0,1-F9/E9) | H9: =IF(AVERAGE('Volumes mensuels'!Q9:S9)=0,0,MAX(0,1-'Volumes mensuels'!V9/AVERAGE('Volumes mensuels'!Q9:S9))) | I9: =MAX(0,1-'Volumes mensuels'!AB9/AVERAGE('Volumes mensuels'!W9:Y9)) | J9: ='Volumes mensuels'!J9 | K9: ='Volumes mensuels'!I9 | L9: =MIN(100,IF(G9>=Paramètres!$B$7,Paramètres!$B$8,IF(G9>=Paramètres!$B$9,Paramètres!$B$10,IF(G9>=Paramètres!$B$11,Paramètres!$B$12,0)))+IF(H9>=Paramètres!$B$13,Paramètres!$B$14,IF(H9>=Paramètres!$B$15,Paramètres!$B$16,0))+IF(J9>Paramètres!$B$17,Paramètres!$B$18,IF(J9>Paramètres!$B$19,Paramètres!$B$20,0))+IF(I9>=Paramètres!$B$21,Paramètres!$B$22,0)+IF(K9<>"",Paramètres!$B$23,0)+IF('Volumes mensuels'!F9="Aucune",Paramètres!$B$24,0)+IF('Volumes mensuels'!G9="Sans engagement",Paramètres!$B$25,0)) | M9: =IF(AND('Volumes mensuels'!H9="Oui",L9>=Paramètres!$B$27),"À surveiller",IF(L9>=Paramètres!$B$26,"Critique",IF(L9>=Paramètres!$B$27,"Élevé",IF(L9>=Paramètres!$B$28,"À surveiller","Sain")))) | N9: =IF(M9="Sain","—",IF(AND(J9>Paramètres!$B$17,G9>=Paramètres!$B$7),"Départ en cours",IF(H9>=Paramètres!$B$13,"Flux Wave qui partent",IF(K9<>"","Incident non soldé",IF('Volumes mensuels'!H9="Oui","Baisse saisonnière probable","Baisse de volume"))))) | O9: =ROUND(E9*Paramètres!$B$6*12,-3) | P9: =VLOOKUP(N9,Paramètres!$A$33:$B$38,2,FALSE)
A10: ='Volumes mensuels'!A10 | B10: ='Volumes mensuels'!B10 | C10: ='Volumes mensuels'!E10 | D10: ='Volumes mensuels'!C10 | E10: =AVERAGE('Volumes mensuels'!K10:M10) | F10: =AVERAGE('Volumes mensuels'!N10:P10) | G10: =MAX(0,1-F10/E10) | H10: =IF(AVERAGE('Volumes mensuels'!Q10:S10)=0,0,MAX(0,1-'Volumes mensuels'!V10/AVERAGE('Volumes mensuels'!Q10:S10))) | I10: =MAX(0,1-'Volumes mensuels'!AB10/AVERAGE('Volumes mensuels'!W10:Y10)) | J10: ='Volumes mensuels'!J10 | K10: ='Volumes mensuels'!I10 | L10: =MIN(100,IF(G10>=Paramètres!$B$7,Paramètres!$B$8,IF(G10>=Paramètres!$B$9,Paramètres!$B$10,IF(G10>=Paramètres!$B$11,Paramètres!$B$12,0)))+IF(H10>=Paramètres!$B$13,Paramètres!$B$14,IF(H10>=Paramètres!$B$15,Paramètres!$B$16,0))+IF(J10>Paramètres!$B$17,Paramètres!$B$18,IF(J10>Paramètres!$B$19,Paramètres!$B$20,0))+IF(I10>=Paramètres!$B$21,Paramètres!$B$22,0)+IF(K10<>"",Paramètres!$B$23,0)+IF('Volumes mensuels'!F10="Aucune",Paramètres!$B$24,0)+IF('Volumes mensuels'!G10="Sans engagement",Paramètres!$B$25,0)) | M10: =IF(AND('Volumes mensuels'!H10="Oui",L10>=Paramètres!$B$27),"À surveiller",IF(L10>=Paramètres!$B$26,"Critique",IF(L10>=Paramètres!$B$27,"Élevé",IF(L10>=Paramètres!$B$28,"À surveiller","Sain")))) | N10: =IF(M10="Sain","—",IF(AND(J10>Paramètres!$B$17,G10>=Paramètres!$B$7),"Départ en cours",IF(H10>=Paramètres!$B$13,"Flux Wave qui partent",IF(K10<>"","Incident non soldé",IF('Volumes mensuels'!H10="Oui","Baisse saisonnière probable","Baisse de volume"))))) | O10: =ROUND(E10*Paramètres!$B$6*12,-3) | P10: =VLOOKUP(N10,Paramètres!$A$33:$B$38,2,FALSE)
A11: ='Volumes mensuels'!A11 | B11: ='Volumes mensuels'!B11 | C11: ='Volumes mensuels'!E11 | D11: ='Volumes mensuels'!C11 | E11: =AVERAGE('Volumes mensuels'!K11:M11) | F11: =AVERAGE('Volumes mensuels'!N11:P11) | G11: =MAX(0,1-F11/E11) | H11: =IF(AVERAGE('Volumes mensuels'!Q11:S11)=0,0,MAX(0,1-'Volumes mensuels'!V11/AVERAGE('Volumes mensuels'!Q11:S11))) | I11: =MAX(0,1-'Volumes mensuels'!AB11/AVERAGE('Volumes mensuels'!W11:Y11)) | J11: ='Volumes mensuels'!J11 | K11: ='Volumes mensuels'!I11 | L11: =MIN(100,IF(G11>=Paramètres!$B$7,Paramètres!$B$8,IF(G11>=Paramètres!$B$9,Paramètres!$B$10,IF(G11>=Paramètres!$B$11,Paramètres!$B$12,0)))+IF(H11>=Paramètres!$B$13,Paramètres!$B$14,IF(H11>=Paramètres!$B$15,Paramètres!$B$16,0))+IF(J11>Paramètres!$B$17,Paramètres!$B$18,IF(J11>Paramètres!$B$19,Paramètres!$B$20,0))+IF(I11>=Paramètres!$B$21,Paramètres!$B$22,0)+IF(K11<>"",Paramètres!$B$23,0)+IF('Volumes mensuels'!F11="Aucune",Paramètres!$B$24,0)+IF('Volumes mensuels'!G11="Sans engagement",Paramètres!$B$25,0)) | M11: =IF(AND('Volumes mensuels'!H11="Oui",L11>=Paramètres!$B$27),"À surveiller",IF(L11>=Paramètres!$B$26,"Critique",IF(L11>=Paramètres!$B$27,"Élevé",IF(L11>=Paramètres!$B$28,"À surveiller","Sain")))) | N11: =IF(M11="Sain","—",IF(AND(J11>Paramètres!$B$17,G11>=Paramètres!$B$7),"Départ en cours",IF(H11>=Paramètres!$B$13,"Flux Wave qui partent",IF(K11<>"","Incident non soldé",IF('Volumes mensuels'!H11="Oui","Baisse saisonnière probable","Baisse de volume"))))) | O11: =ROUND(E11*Paramètres!$B$6*12,-3) | P11: =VLOOKUP(N11,Paramètres!$A$33:$B$38,2,FALSE)
A12: ='Volumes mensuels'!A12 | B12: ='Volumes mensuels'!B12 | C12: ='Volumes mensuels'!E12 | D12: ='Volumes mensuels'!C12 | E12: =AVERAGE('Volumes mensuels'!K12:M12) | F12: =AVERAGE('Volumes mensuels'!N12:P12) | G12: =MAX(0,1-F12/E12) | H12: =IF(AVERAGE('Volumes mensuels'!Q12:S12)=0,0,MAX(0,1-'Volumes mensuels'!V12/AVERAGE('Volumes mensuels'!Q12:S12))) | I12: =MAX(0,1-'Volumes mensuels'!AB12/AVERAGE('Volumes mensuels'!W12:Y12)) | J12: ='Volumes mensuels'!J12 | K12: ='Volumes mensuels'!I12 | L12: =MIN(100,IF(G12>=Paramètres!$B$7,Paramètres!$B$8,IF(G12>=Paramètres!$B$9,Paramètres!$B$10,IF(G12>=Paramètres!$B$11,Paramètres!$B$12,0)))+IF(H12>=Paramètres!$B$13,Paramètres!$B$14,IF(H12>=Paramètres!$B$15,Paramètres!$B$16,0))+IF(J12>Paramètres!$B$17,Paramètres!$B$18,IF(J12>Paramètres!$B$19,Paramètres!$B$20,0))+IF(I12>=Paramètres!$B$21,Paramètres!$B$22,0)+IF(K12<>"",Paramètres!$B$23,0)+IF('Volumes mensuels'!F12="Aucune",Paramètres!$B$24,0)+IF('Volumes mensuels'!G12="Sans engagement",Paramètres!$B$25,0)) | M12: =IF(AND('Volumes mensuels'!H12="Oui",L12>=Paramètres!$B$27),"À surveiller",IF(L12>=Paramètres!$B$26,"Critique",IF(L12>=Paramètres!$B$27,"Élevé",IF(L12>=Paramètres!$B$28,"À surveiller","Sain")))) | N12: =IF(M12="Sain","—",IF(AND(J12>Paramètres!$B$17,G12>=Paramètres!$B$7),"Départ en cours",IF(H12>=Paramètres!$B$13,"Flux Wave qui partent",IF(K12<>"","Incident non soldé",IF('Volumes mensuels'!H12="Oui","Baisse saisonnière probable","Baisse de volume"))))) | O12: =ROUND(E12*Paramètres!$B$6*12,-3) | P12: =VLOOKUP(N12,Paramètres!$A$33:$B$38,2,FALSE)
A13: ='Volumes mensuels'!A13 | B13: ='Volumes mensuels'!B13 | C13: ='Volumes mensuels'!E13 | D13: ='Volumes mensuels'!C13 | E13: =AVERAGE('Volumes mensuels'!K13:M13) | F13: =AVERAGE('Volumes mensuels'!N13:P13) | G13: =MAX(0,1-F13/E13) | H13: =IF(AVERAGE('Volumes mensuels'!Q13:S13)=0,0,MAX(0,1-'Volumes mensuels'!V13/AVERAGE('Volumes mensuels'!Q13:S13))) | I13: =MAX(0,1-'Volumes mensuels'!AB13/AVERAGE('Volumes mensuels'!W13:Y13)) | J13: ='Volumes mensuels'!J13 | K13: ='Volumes mensuels'!I13 | L13: =MIN(100,IF(G13>=Paramètres!$B$7,Paramètres!$B$8,IF(G13>=Paramètres!$B$9,Paramètres!$B$10,IF(G13>=Paramètres!$B$11,Paramètres!$B$12,0)))+IF(H13>=Paramètres!$B$13,Paramètres!$B$14,IF(H13>=Paramètres!$B$15,Paramètres!$B$16,0))+IF(J13>Paramètres!$B$17,Paramètres!$B$18,IF(J13>Paramètres!$B$19,Paramètres!$B$20,0))+IF(I13>=Paramètres!$B$21,Paramètres!$B$22,0)+IF(K13<>"",Paramètres!$B$23,0)+IF('Volumes mensuels'!F13="Aucune",Paramètres!$B$24,0)+IF('Volumes mensuels'!G13="Sans engagement",Paramètres!$B$25,0)) | M13: =IF(AND('Volumes mensuels'!H13="Oui",L13>=Paramètres!$B$27),"À surveiller",IF(L13>=Paramètres!$B$26,"Critique",IF(L13>=Paramètres!$B$27,"Élevé",IF(L13>=Paramètres!$B$28,"À surveiller","Sain")))) | N13: =IF(M13="Sain","—",IF(AND(J13>Paramètres!$B$17,G13>=Paramètres!$B$7),"Départ en cours",IF(H13>=Paramètres!$B$13,"Flux Wave qui partent",IF(K13<>"","Incident non soldé",IF('Volumes mensuels'!H13="Oui","Baisse saisonnière probable","Baisse de volume"))))) | O13: =ROUND(E13*Paramètres!$B$6*12,-3) | P13: =VLOOKUP(N13,Paramètres!$A$33:$B$38,2,FALSE)
A14: ='Volumes mensuels'!A14 | B14: ='Volumes mensuels'!B14 | C14: ='Volumes mensuels'!E14 | D14: ='Volumes mensuels'!C14 | E14: =AVERAGE('Volumes mensuels'!K14:M14) | F14: =AVERAGE('Volumes mensuels'!N14:P14) | G14: =MAX(0,1-F14/E14) | H14: =IF(AVERAGE('Volumes mensuels'!Q14:S14)=0,0,MAX(0,1-'Volumes mensuels'!V14/AVERAGE('Volumes mensuels'!Q14:S14))) | I14: =MAX(0,1-'Volumes mensuels'!AB14/AVERAGE('Volumes mensuels'!W14:Y14)) | J14: ='Volumes mensuels'!J14 | K14: ='Volumes mensuels'!I14 | L14: =MIN(100,IF(G14>=Paramètres!$B$7,Paramètres!$B$8,IF(G14>=Paramètres!$B$9,Paramètres!$B$10,IF(G14>=Paramètres!$B$11,Paramètres!$B$12,0)))+IF(H14>=Paramètres!$B$13,Paramètres!$B$14,IF(H14>=Paramètres!$B$15,Paramètres!$B$16,0))+IF(J14>Paramètres!$B$17,Paramètres!$B$18,IF(J14>Paramètres!$B$19,Paramètres!$B$20,0))+IF(I14>=Paramètres!$B$21,Paramètres!$B$22,0)+IF(K14<>"",Paramètres!$B$23,0)+IF('Volumes mensuels'!F14="Aucune",Paramètres!$B$24,0)+IF('Volumes mensuels'!G14="Sans engagement",Paramètres!$B$25,0)) | M14: =IF(AND('Volumes mensuels'!H14="Oui",L14>=Paramètres!$B$27),"À surveiller",IF(L14>=Paramètres!$B$26,"Critique",IF(L14>=Paramètres!$B$27,"Élevé",IF(L14>=Paramètres!$B$28,"À surveiller","Sain")))) | N14: =IF(M14="Sain","—",IF(AND(J14>Paramètres!$B$17,G14>=Paramètres!$B$7),"Départ en cours",IF(H14>=Paramètres!$B$13,"Flux Wave qui partent",IF(K14<>"","Incident non soldé",IF('Volumes mensuels'!H14="Oui","Baisse saisonnière probable","Baisse de volume"))))) | O14: =ROUND(E14*Paramètres!$B$6*12,-3) | P14: =VLOOKUP(N14,Paramètres!$A$33:$B$38,2,FALSE)
A15: ='Volumes mensuels'!A15 | B15: ='Volumes mensuels'!B15 | C15: ='Volumes mensuels'!E15 | D15: ='Volumes mensuels'!C15 | E15: =AVERAGE('Volumes mensuels'!K15:M15) | F15: =AVERAGE('Volumes mensuels'!N15:P15) | G15: =MAX(0,1-F15/E15) | H15: =IF(AVERAGE('Volumes mensuels'!Q15:S15)=0,0,MAX(0,1-'Volumes mensuels'!V15/AVERAGE('Volumes mensuels'!Q15:S15))) | I15: =MAX(0,1-'Volumes mensuels'!AB15/AVERAGE('Volumes mensuels'!W15:Y15)) | J15: ='Volumes mensuels'!J15 | K15: ='Volumes mensuels'!I15 | L15: =MIN(100,IF(G15>=Paramètres!$B$7,Paramètres!$B$8,IF(G15>=Paramètres!$B$9,Paramètres!$B$10,IF(G15>=Paramètres!$B$11,Paramètres!$B$12,0)))+IF(H15>=Paramètres!$B$13,Paramètres!$B$14,IF(H15>=Paramètres!$B$15,Paramètres!$B$16,0))+IF(J15>Paramètres!$B$17,Paramètres!$B$18,IF(J15>Paramètres!$B$19,Paramètres!$B$20,0))+IF(I15>=Paramètres!$B$21,Paramètres!$B$22,0)+IF(K15<>"",Paramètres!$B$23,0)+IF('Volumes mensuels'!F15="Aucune",Paramètres!$B$24,0)+IF('Volumes mensuels'!G15="Sans engagement",Paramètres!$B$25,0)) | M15: =IF(AND('Volumes mensuels'!H15="Oui",L15>=Paramètres!$B$27),"À surveiller",IF(L15>=Paramètres!$B$26,"Critique",IF(L15>=Paramètres!$B$27,"Élevé",IF(L15>=Paramètres!$B$28,"À surveiller","Sain")))) | N15: =IF(M15="Sain","—",IF(AND(J15>Paramètres!$B$17,G15>=Paramètres!$B$7),"Départ en cours",IF(H15>=Paramètres!$B$13,"Flux Wave qui partent",IF(K15<>"","Incident non soldé",IF('Volumes mensuels'!H15="Oui","Baisse saisonnière probable","Baisse de volume"))))) | O15: =ROUND(E15*Paramètres!$B$6*12,-3) | P15: =VLOOKUP(N15,Paramètres!$A$33:$B$38,2,FALSE)
A16: ='Volumes mensuels'!A16 | B16: ='Volumes mensuels'!B16 | C16: ='Volumes mensuels'!E16 | D16: ='Volumes mensuels'!C16 | E16: =AVERAGE('Volumes mensuels'!K16:M16) | F16: =AVERAGE('Volumes mensuels'!N16:P16) | G16: =MAX(0,1-F16/E16) | H16: =IF(AVERAGE('Volumes mensuels'!Q16:S16)=0,0,MAX(0,1-'Volumes mensuels'!V16/AVERAGE('Volumes mensuels'!Q16:S16))) | I16: =MAX(0,1-'Volumes mensuels'!AB16/AVERAGE('Volumes mensuels'!W16:Y16)) | J16: ='Volumes mensuels'!J16 | K16: ='Volumes mensuels'!I16 | L16: =MIN(100,IF(G16>=Paramètres!$B$7,Paramètres!$B$8,IF(G16>=Paramètres!$B$9,Paramètres!$B$10,IF(G16>=Paramètres!$B$11,Paramètres!$B$12,0)))+IF(H16>=Paramètres!$B$13,Paramètres!$B$14,IF(H16>=Paramètres!$B$15,Paramètres!$B$16,0))+IF(J16>Paramètres!$B$17,Paramètres!$B$18,IF(J16>Paramètres!$B$19,Paramètres!$B$20,0))+IF(I16>=Paramètres!$B$21,Paramètres!$B$22,0)+IF(K16<>"",Paramètres!$B$23,0)+IF('Volumes mensuels'!F16="Aucune",Paramètres!$B$24,0)+IF('Volumes mensuels'!G16="Sans engagement",Paramètres!$B$25,0)) | M16: =IF(AND('Volumes mensuels'!H16="Oui",L16>=Paramètres!$B$27),"À surveiller",IF(L16>=Paramètres!$B$26,"Critique",IF(L16>=Paramètres!$B$27,"Élevé",IF(L16>=Paramètres!$B$28,"À surveiller","Sain")))) | N16: =IF(M16="Sain","—",IF(AND(J16>Paramètres!$B$17,G16>=Paramètres!$B$7),"Départ en cours",IF(H16>=Paramètres!$B$13,"Flux Wave qui partent",IF(K16<>"","Incident non soldé",IF('Volumes mensuels'!H16="Oui","Baisse saisonnière probable","Baisse de volume"))))) | O16: =ROUND(E16*Paramètres!$B$6*12,-3) | P16: =VLOOKUP(N16,Paramètres!$A$33:$B$38,2,FALSE)
A17: ='Volumes mensuels'!A17 | B17: ='Volumes mensuels'!B17 | C17: ='Volumes mensuels'!E17 | D17: ='Volumes mensuels'!C17 | E17: =AVERAGE('Volumes mensuels'!K17:M17) | F17: =AVERAGE('Volumes mensuels'!N17:P17) | G17: =MAX(0,1-F17/E17) | H17: =IF(AVERAGE('Volumes mensuels'!Q17:S17)=0,0,MAX(0,1-'Volumes mensuels'!V17/AVERAGE('Volumes mensuels'!Q17:S17))) | I17: =MAX(0,1-'Volumes mensuels'!AB17/AVERAGE('Volumes mensuels'!W17:Y17)) | J17: ='Volumes mensuels'!J17 | K17: ='Volumes mensuels'!I17 | L17: =MIN(100,IF(G17>=Paramètres!$B$7,Paramètres!$B$8,IF(G17>=Paramètres!$B$9,Paramètres!$B$10,IF(G17>=Paramètres!$B$11,Paramètres!$B$12,0)))+IF(H17>=Paramètres!$B$13,Paramètres!$B$14,IF(H17>=Paramètres!$B$15,Paramètres!$B$16,0))+IF(J17>Paramètres!$B$17,Paramètres!$B$18,IF(J17>Paramètres!$B$19,Paramètres!$B$20,0))+IF(I17>=Paramètres!$B$21,Paramètres!$B$22,0)+IF(K17<>"",Paramètres!$B$23,0)+IF('Volumes mensuels'!F17="Aucune",Paramètres!$B$24,0)+IF('Volumes mensuels'!G17="Sans engagement",Paramètres!$B$25,0)) | M17: =IF(AND('Volumes mensuels'!H17="Oui",L17>=Paramètres!$B$27),"À surveiller",IF(L17>=Paramètres!$B$26,"Critique",IF(L17>=Paramètres!$B$27,"Élevé",IF(L17>=Paramètres!$B$28,"À surveiller","Sain")))) | N17: =IF(M17="Sain","—",IF(AND(J17>Paramètres!$B$17,G17>=Paramètres!$B$7),"Départ en cours",IF(H17>=Paramètres!$B$13,"Flux Wave qui partent",IF(K17<>"","Incident non soldé",IF('Volumes mensuels'!H17="Oui","Baisse saisonnière probable","Baisse de volume"))))) | O17: =ROUND(E17*Paramètres!$B$6*12,-3) | P17: =VLOOKUP(N17,Paramètres!$A$33:$B$38,2,FALSE)
... A45: ='Volumes mensuels'!A45 | B45: ='Volumes mensuels'!B45 | C45: ='Volumes mensuels'!E45 | D45: ='Volumes mensuels'!C45 | E45: =AVERAGE('Volumes mensuels'!K45:M45) | F45: =AVERAGE('Volumes mensuels'!N45:P45) | G45: =MAX(0,1-F45/E45) | H45: =IF(AVERAGE('Volumes mensuels'!Q45:S45)=0,0,MAX(0,1-'Volumes mensuels'!V45/AVERAGE('Volumes mensuels'!Q45:S45))) | I45: =MAX(0,1-'Volumes mensuels'!AB45/AVERAGE('Volumes mensuels'!W45:Y45)) | J45: ='Volumes mensuels'!J45 | K45: ='Volumes mensuels'!I45 | L45: =MIN(100,IF(G45>=Paramètres!$B$7,Paramètres!$B$8,IF(G45>=Paramètres!$B$9,Paramètres!$B$10,IF(G45>=Paramètres!$B$11,Paramètres!$B$12,0)))+IF(H45>=Paramètres!$B$13,Paramètres!$B$14,IF(H45>=Paramètres!$B$15,Paramètres!$B$16,0))+IF(J45>Paramètres!$B$17,Paramètres!$B$18,IF(J45>Paramètres!$B$19,Paramètres!$B$20,0))+IF(I45>=Paramètres!$B$21,Paramètres!$B$22,0)+IF(K45<>"",Paramètres!$B$23,0)+IF('Volumes mensuels'!F45="Aucune",Paramètres!$B$24,0)+IF('Volumes mensuels'!G45="Sans engagement",Paramètres!$B$25,0)) | M45: =IF(AND('Volumes mensuels'!H45="Oui",L45>=Paramètres!$B$27),"À surveiller",IF(L45>=Paramètres!$B$26,"Critique",IF(L45>=Paramètres!$B$27,"Élevé",IF(L45>=Paramètres!$B$28,"À surveiller","Sain")))) | N45: =IF(M45="Sain","—",IF(AND(J45>Paramètres!$B$17,G45>=Paramètres!$B$7),"Départ en cours",IF(H45>=Paramètres!$B$13,"Flux Wave qui partent",IF(K45<>"","Incident non soldé",IF('Volumes mensuels'!H45="Oui","Baisse saisonnière probable","Baisse de volume"))))) | O45: =ROUND(E45*Paramètres!$B$6*12,-3) | P45: =VLOOKUP(N45,Paramètres!$A$33:$B$38,2,FALSE)
B47: Total (40 clients) | E47: =SUM(E6:E45) | F47: =SUM(F6:F45) | O47: =SUM(O6:O45)

Sheet Plan d'action
C1: Plan d'action du mois : comptes critiques et élevés
A2: FICTIF : clients, volumes et incidents inventés pour illustrer la méthode. Aucun nom, montant ni date ne vient de Julaya.
A3: Liste arrêtée sur l'export du 21/10/2026. Rien ne part tant que « Validé par » est vide.
A5: ID | B5: Client | C5: Score | D5: Niveau | E5: Signal principal | F5: Revenu annuel en jeu | G5: Qui agit | H5: Avant le | I5: Premier message (brouillon, à valider) | J5: Validé par | K5: Statut | L5: Réponse du client (ses mots) | M5: Raison réelle | N5: Issue
A6: JUL-102 | B6: Bâtirama BTP | C6: 100 | D6: Critique | E6: Départ en cours | F6: 28552000 | G6: Directeur commercial | H6: 46318 | I6: Bonjour ⟦Madame / Monsieur + nom du contact⟧, c'est Serge de Julaya. Nous voyons moins de paiements passer par votre compte depuis juillet et je voulais vous en parler directement. Est-ce que quelque chose ne vous convient plus chez nous ? Je peux passer vous voir ou vous appeler cette semaine, au moment qui vous arrange. | K6: À valider
A7: JUL-115 | B7: Bouaké Agro Plus | C7: 100 | D7: Critique | E7: Départ en cours | F7: 14087000 | G7: Directeur commercial | H7: 46318 | I7: Bonjour ⟦Madame / Monsieur + nom du contact⟧, c'est Mariam de Julaya. Nous voyons moins de paiements passer par votre compte depuis juillet et je voulais vous en parler directement. Est-ce que quelque chose ne vous convient plus chez nous ? Je peux passer vous voir ou vous appeler cette semaine, au moment qui vous arrange. | K7: À valider
A8: JUL-129 | B8: Transports Express Ouest | C8: 100 | D8: Critique | E8: Départ en cours | F8: 8237000 | G8: Directeur commercial | H8: 46318 | I8: Bonjour ⟦Madame / Monsieur + nom du contact⟧, c'est Aïcha de Julaya. Nous voyons moins de paiements passer par votre compte depuis juillet et je voulais vous en parler directement. Est-ce que quelque chose ne vous convient plus chez nous ? Je peux passer vous voir ou vous appeler cette semaine, au moment qui vous arrange. | K8: À valider
A9: JUL-120 | B9: Restaurants Gbaka & Co | C9: 100 | D9: Critique | E9: Départ en cours | F9: 4381000 | G9: Directeur commercial | H9: 46318 | I9: Bonjour ⟦Madame / Monsieur + nom du contact⟧, c'est Yannick de Julaya. Nous voyons moins de paiements passer par votre compte depuis juillet et je voulais vous en parler directement. Est-ce que quelque chose ne vous convient plus chez nous ? Je peux passer vous voir ou vous appeler cette semaine, au moment qui vous arrange. | K9: À valider
A10: JUL-133 | B10: Boulangeries Délices | C10: 68 | D10: Critique | E10: Flux Wave qui partent | F10: 3967000 | G10: Directeur commercial | H10: 46318 | I10: Bonjour ⟦Madame / Monsieur + nom du contact⟧, c'est Aïcha de Julaya. Je prépare la revue de votre compte et je vois que vos paiements vers Wave ont baissé depuis juillet. Si une partie passe désormais par un autre outil, je vous propose de chiffrer ensemble ce que ça vous coûte vraiment, validations et rapprochements compris. Trente minutes la semaine prochaine ? | K10: À valider
A11: JUL-107 | B11: Garde Sûre Sécurité | C11: 55 | D11: Élevé | E11: Flux Wave qui partent | F11: 20164000 | G11: Chargé de compte (Mariam D.) | H11: 46323 | I11: Bonjour ⟦Madame / Monsieur + nom du contact⟧, c'est Mariam de Julaya. Je prépare la revue de votre compte et je vois que vos paiements vers Wave ont baissé depuis juillet. Si une partie passe désormais par un autre outil, je vous propose de chiffrer ensemble ce que ça vous coûte vraiment, validations et rapprochements compris. Trente minutes la semaine prochaine ? | K11: À valider
A12: JUL-105 | B12: Kodjo Logistique | C12: 55 | D12: Élevé | E12: Flux Wave qui partent | F12: 14872000 | G12: Chargé de compte (Aïcha K.) | H12: 46323 | I12: Bonjour ⟦Madame / Monsieur + nom du contact⟧, c'est Aïcha de Julaya. Je prépare la revue de votre compte et je vois que vos paiements vers Wave ont baissé depuis juillet. Si une partie passe désormais par un autre outil, je vous propose de chiffrer ensemble ce que ça vous coûte vraiment, validations et rapprochements compris. Trente minutes la semaine prochaine ? | K12: À valider
A13: JUL-124 | B13: Marché Frais Cocody | C13: 55 | D13: Élevé | E13: Flux Wave qui partent | F13: 5558000 | G13: Chargé de compte (Yannick B.) | H13: 46323 | I13: Bonjour ⟦Madame / Monsieur + nom du contact⟧, c'est Yannick de Julaya. Je prépare la revue de votre compte et je vois que vos paiements vers Wave ont baissé depuis juillet. Si une partie passe désormais par un autre outil, je vous propose de chiffrer ensemble ce que ça vous coûte vraiment, validations et rapprochements compris. Trente minutes la semaine prochaine ? | K13: À valider
A14: JUL-101 | B14: Sotradis Négoce | C14: 52 | D14: Élevé | E14: Flux Wave qui partent | F14: 32940000 | G14: Chargé de compte (Aïcha K.) | H14: 46323 | I14: Bonjour ⟦Madame / Monsieur + nom du contact⟧, c'est Aïcha de Julaya. Je prépare la revue de votre compte et je vois que vos paiements vers Wave ont baissé depuis juillet. Si une partie passe désormais par un autre outil, je vous propose de chiffrer ensemble ce que ça vous coûte vraiment, validations et rapprochements compris. Trente minutes la semaine prochaine ? | K14: À valider
A15: JUL-117 | B15: Nettoyage Pro Abidjan | C15: 47 | D15: Élevé | E15: Flux Wave qui partent | F15: 10588000 | G15: Chargé de compte (Aïcha K.) | H15: 46323 | I15: Bonjour ⟦Madame / Monsieur + nom du contact⟧, c'est Aïcha de Julaya. Je prépare la revue de votre compte et je vois que vos paiements vers Wave ont baissé depuis juillet. Si une partie passe désormais par un autre outil, je vous propose de chiffrer ensemble ce que ça vous coûte vraiment, validations et rapprochements compris. Trente minutes la semaine prochaine ? | K15: À valider
A16: JUL-112 | B16: Hôtel Lagune Bleue | C16: 47 | D16: Élevé | E16: Flux Wave qui partent | F16: 5098000 | G16: Chargé de compte (Yannick B.) | H16: 46323 | I16: Bonjour ⟦Madame / Monsieur + nom du contact⟧, c'est Yannick de Julaya. Je prépare la revue de votre compte et je vois que vos paiements vers Wave ont baissé depuis juillet. Si une partie passe désormais par un autre outil, je vous propose de chiffrer ensemble ce que ça vous coûte vraiment, validations et rapprochements compris. Trente minutes la semaine prochaine ? | K16: À valider
A17: JUL-110 | B17: Dakar Fret Services | C17: 42 | D17: Élevé | E17: Incident non soldé | F17: 13252000 | G17: Chargé de compte (Serge T.) | H17: 46323 | I17: Bonjour ⟦Madame / Monsieur + nom du contact⟧, c'est Serge de Julaya. Je reviens vers vous au sujet de votre réclamation (lot de salaires en échec). Je veux m'assurer qu'elle est bien réglée de votre côté et vous dire ce que nous avons changé. Je peux vous appeler cette semaine ? | K17: À valider
A18: JUL-126 | B18: Yamoussoukro Matériaux | C18: 42 | D18: Élevé | E18: Incident non soldé | F18: 10397000 | G18: Chargé de compte (Serge T.) | H18: 46323 | I18: Bonjour ⟦Madame / Monsieur + nom du contact⟧, c'est Serge de Julaya. Je reviens vers vous au sujet de votre réclamation (délai de virement bancaire). Je veux m'assurer qu'elle est bien réglée de votre côté et vous dire ce que nous avons changé. Je peux vous appeler cette semaine ? | K18: À valider
