Workbook

Sheet À lire
B2: TAJ PLAST · Suivi des commandes revendeurs
B3: Modèle prêt à l'emploi · relances des impayés et des retards calculées chaque jour · préparé par Kouassi (Yelema), 27/10/2026
B5: LES LIGNES REVENDEURS ET COMMANDES SONT FICTIVES : elles montrent le fonctionnement. Les supprimer avant la mise en service.
B7: Comment ça marche
B8: 1. Paramètres : régler une fois les délais de relance, le délai de paiement et le plafond d'encours par défaut. Ce sont des choix de la direction, marqués « à décider ».
B9: 2. Revendeurs : une ligne par revendeur, avec son délai de paiement et son plafond d'encours. L'encours et les impayés se calculent seuls.
B10: 3. Commandes : on ne saisit que les cases blanches (date, revendeur, produit, quantité, prix, dates de livraison, montant payé). Les cases grisées se calculent.
B11: 4. Relances du jour : chaque matin, la liste des paiements à relancer et des livraisons en retard, avec le message WhatsApp déjà rédigé.
B12: 5. Tableau de bord : chiffre du mois, encours, impayés échus, retards, revendeurs au-dessus de leur plafond.
B14: Les règles de relance (modifiables dans Paramètres)
B15: • Échéance = date de livraison + délai de paiement du revendeur (ou délai par défaut).
B16: • Relance 1 à J+3 après l'échéance, relance 2 à J+10, relance 3 à J+20 : appel du responsable commercial ou de la direction.
... B21: Le tableur prépare chaque message, mais n'envoie rien. On relit, on inscrit son nom dans « Validé par », on envoie, puis on note la date dans « Relance envoyée le ». Ainsi, le même revendeur n'est jamais relancé deux fois le même jour.

Sheet Tableau de bord
A1: Tableau de bord des revendeurs
A2: ="Situation au "&TEXT(Paramètres!$B$4,"dd/mm/yyyy")
A4: Indicateur | B4: Valeur | D4: Impayés échus par revendeur
A5: Commandes du mois | B5: =COUNTIFS(Commandes!$B:$B,">="&(EOMONTH(Paramètres!$B$4,-1)+1),Commandes!$B:$B,"<="&Paramètres!$B$4)
A6: Chiffre d'affaires HT du mois (FCFA) | B6: =SUMIFS(Commandes!$H:$H,Commandes!$B:$B,">="&(EOMONTH(Paramètres!$B$4,-1)+1),Commandes!$B:$B,"<="&Paramètres!$B$4)
A7: Encours total (FCFA) | B7: =SUM(Commandes!$O:$O)
A8: dont impayés échus (FCFA) | B8: =SUMIFS(Commandes!$O:$O,Commandes!$P:$P,">0")
A9: Paiements à relancer aujourd'hui | B9: =COUNTIF(Commandes!$Q:$Q,"Relance*")
A10: Livraisons en retard | B10: =COUNTIF(Commandes!$K:$K,"En retard")
A11: Revendeurs au-dessus de leur plafond | B11: =COUNTIF(Revendeurs!$L:$L,"Dépassement*")

Sheet Paramètres
A1: Paramètres
A3: Paramètre | B3: Valeur | C3: Commentaire
A4: Date du jour | B4: =TODAY() | C4: Se met à jour seule
A5: Relance 1 : jours après l'échéance | B5: 3 | C5: À décider par la direction
A6: Relance 2 : jours après l'échéance | B6: 10 | C6: À décider par la direction
A7: Relance 3 (appel de la direction) : jours après l'échéance | B7: 20 | C7: À décider par la direction
A8: Tolérance de retard de livraison (jours) | B8: 0 | C8: 0 = en retard dès le lendemain de la date promise
A9: Délai de paiement par défaut (jours) | B9: 30 | C9: À décider par la direction (valeur d'exemple)
A10: Plafond d'encours par défaut (FCFA) | B10: 2000000 | C10: À décider par la direction (valeur d'exemple)
A11: Signature des messages | B11: Le service commercial Taj Plast | C11: Remplacer par le prénom du commercial
A12: Téléphone affiché dans les messages | B12: 27 21 37 66 66 | C12: Standard publié sur tajplast.com

Sheet Produits
A1: Produit | B1: Famille | C1: Colisage (pièces par colis) | D1: Prix revendeur HT (FCFA) | E1: Source
A2: Chaise Ibiza | B2: Mobilier | E2: tajplast.com (nouveautés)
A3: Table Choco | B3: Mobilier | E3: tajplast.com / catalogue 2025
A4: Table ronde (diamètre 90 cm) | B4: Mobilier | E4: catalogue 2025
A5: Table familiale 6 places | B5: Mobilier | E5: catalogue 2025
A6: Armoire de rangement | B6: Mobilier | E6: catalogue 2025
A7: Tiroir de rangement | B7: Mobilier | E7: catalogue 2025
A8: Poubelle à pédale | B8: Ménage | E8: tajplast.com (nouveautés)
A9: Bidon 2 L | B9: Bidons | C9: 24 | E9: catalogue 2025, p. 24
A10: Bidon 5 L | B10: Bidons | C10: 24 | E10: catalogue 2025, p. 24
A11: Bidon 10 L | B11: Bidons | C11: 6 | E11: catalogue 2025, p. 24
A12: Bidon 20 L | B12: Bidons | C12: 6 | E12: catalogue 2025, p. 24
A13: Bidon 25 L | B13: Bidons | C13: 5 | E13: catalogue 2025, p. 24
A14: Arrosoir 15 L | B14: Ménage | C14: 6 | E14: catalogue 2025, p. 24
A15: Cuve de stockage (capacité à préciser) | B15: Assainissement | E15: tajplast.com
A16: Fosse septique (modèle à préciser) | B16: Assainissement | E16: tajplast.com
A17: Puits d'infiltration | B17: Assainissement | E17: tajplast.com
A18: Tube orange (rouleau) | B18: Assainissement | E18: tajplast.com
A19: Bouteille PET (format à préciser) | B19: Emballage | E19: catalogue 2025
A21: Prix revendeur : à renseigner par Taj Plast (grille non communiquée). Ajouter les autres références du catalogue à la suite.

Sheet Revendeurs
A1: Code | B1: Revendeur | C1: Ville / commune | D1: Canal | E1: Contact | F1: WhatsApp | G1: Délai de paiement (jours) | H1: Plafond d'encours (FCFA) | I1: Encours (FCFA) | J1: Utilisation du plafond | K1: Impayés échus (FCFA) | L1: Alerte encours
A2: R001 | B2: Revendeur exemple A (FICTIF) | C2: Adjamé | D2: Grossiste | E2: M. Exemple | F2: 07 00 00 00 01 | G2: 30 | H2: 3000000 | I2: =IF(A2="","",SUMIFS(Commandes!$O:$O,Commandes!$C:$C,A2)) | J2: =IF(A2="","",IFERROR(I2/IF(H2="",Paramètres!$B$10,H2),"")) | K2: =IF(A2="","",SUMIFS(Commandes!$O:$O,Commandes!$C:$C,A2,Commandes!$P:$P,">0")) | L2: =IF(A2="","",IF(I2>IF(H2="",Paramètres!$B$10,H2),"Dépassement : livraison à valider par la direction",IF(J2>=0.8,"Proche du plafond","OK")))
A3: R002 | B3: Quincaillerie exemple B (FICTIF) | C3: Yopougon | D3: Quincaillerie | E3: Mme Exemple | F3: 07 00 00 00 02 | G3: 15 | H3: 1500000 | I3: =IF(A3="","",SUMIFS(Commandes!$O:$O,Commandes!$C:$C,A3)) | J3: =IF(A3="","",IFERROR(I3/IF(H3="",Paramètres!$B$10,H3),"")) | K3: =IF(A3="","",SUMIFS(Commandes!$O:$O,Commandes!$C:$C,A3,Commandes!$P:$P,">0")) | L3: =IF(A3="","",IF(I3>IF(H3="",Paramètres!$B$10,H3),"Dépassement : livraison à valider par la direction",IF(J3>=0.8,"Proche du plafond","OK")))
A4: R003 | B4: Supermarché exemple C (FICTIF) | C4: Cocody | D4: Supermarché | E4: Service achats | F4: 07 00 00 00 03 | G4: 45 | H4: 5000000 | I4: =IF(A4="","",SUMIFS(Commandes!$O:$O,Commandes!$C:$C,A4)) | J4: =IF(A4="","",IFERROR(I4/IF(H4="",Paramètres!$B$10,H4),"")) | K4: =IF(A4="","",SUMIFS(Commandes!$O:$O,Commandes!$C:$C,A4,Commandes!$P:$P,">0")) | L4: =IF(A4="","",IF(I4>IF(H4="",Paramètres!$B$10,H4),"Dépassement : livraison à valider par la direction",IF(J4>=0.8,"Proche du plafond","OK")))
A5: R004 | B5: Revendeur exemple D (FICTIF) | C5: Bouaké | D5: Grossiste | E5: M. Exemple | F5: 07 00 00 00 04 | G5: 30 | I5: =IF(A5="","",SUMIFS(Commandes!$O:$O,Commandes!$C:$C,A5)) | J5: =IF(A5="","",IFERROR(I5/IF(H5="",Paramètres!$B$10,H5),"")) | K5: =IF(A5="","",SUMIFS(Commandes!$O:$O,Commandes!$C:$C,A5,Commandes!$P:$P,">0")) | L5: =IF(A5="","",IF(I5>IF(H5="",Paramètres!$B$10,H5),"Dépassement : livraison à valider par la direction",IF(J5>=0.8,"Proche du plafond","OK")))
A6: R005 | B6: BTP exemple E (FICTIF) | C6: Bingerville | D6: BTP | E6: Conducteur de travaux | F6: 07 00 00 00 05 | G6: 30 | H6: 1000000 | I6: =IF(A6="","",SUMIFS(Commandes!$O:$O,Commandes!$C:$C,A6)) | J6: =IF(A6="","",IFERROR(I6/IF(H6="",Paramètres!$B$10,H6),"")) | K6: =IF(A6="","",SUMIFS(Commandes!$O:$O,Commandes!$C:$C,A6,Commandes!$P:$P,">0")) | L6: =IF(A6="","",IF(I6>IF(H6="",Paramètres!$B$10,H6),"Dépassement : livraison à valider par la direction",IF(J6>=0.8,"Proche du plafond","OK")))
I7: =IF(A7="","",SUMIFS(Commandes!$O:$O,Commandes!$C:$C,A7)) | J7: =IF(A7="","",IFERROR(I7/IF(H7="",Paramètres!$B$10,H7),"")) | K7: =IF(A7="","",SUMIFS(Commandes!$O:$O,Commandes!$C:$C,A7,Commandes!$P:$P,">0")) | L7: =IF(A7="","",IF(I7>IF(H7="",Paramètres!$B$10,H7),"Dépassement : livraison à valider par la direction",IF(J7>=0.8,"Proche du plafond","OK")))
I8: =IF(A8="","",SUMIFS(Commandes!$O:$O,Commandes!$C:$C,A8)) | J8: =IF(A8="","",IFERROR(I8/IF(H8="",Paramètres!$B$10,H8),"")) | K8: =IF(A8="","",SUMIFS(Commandes!$O:$O,Commandes!$C:$C,A8,Commandes!$P:$P,">0")) | L8: =IF(A8="","",IF(I8>IF(H8="",Paramètres!$B$10,H8),"Dépassement : livraison à valider par la direction",IF(J8>=0.8,"Proche du plafond","OK")))
I9: =IF(A9="","",SUMIFS(Commandes!$O:$O,Commandes!$C:$C,A9)) | J9: =IF(A9="","",IFERROR(I9/IF(H9="",Paramètres!$B$10,H9),"")) | K9: =IF(A9="","",SUMIFS(Commandes!$O:$O,Commandes!$C:$C,A9,Commandes!$P:$P,">0")) | L9: =IF(A9="","",IF(I9>IF(H9="",Paramètres!$B$10,H9),"Dépassement : livraison à valider par la direction",IF(J9>=0.8,"Proche du plafond","OK")))
I10: =IF(A10="","",SUMIFS(Commandes!$O:$O,Commandes!$C:$C,A10)) | J10: =IF(A10="","",IFERROR(I10/IF(H10="",Paramètres!$B$10,H10),"")) | K10: =IF(A10="","",SUMIFS(Commandes!$O:$O,Commandes!$C:$C,A10,Commandes!$P:$P,">0")) | L10: =IF(A10="","",IF(I10>IF(H10="",Paramètres!$B$10,H10),"Dépassement : livraison à valider par la direction",IF(J10>=0.8,"Proche du plafond","OK")))
I11: =IF(A11="","",SUMIFS(Commandes!$O:$O,Commandes!$C:$C,A11)) | J11: =IF(A11="","",IFERROR(I11/IF(H11="",Paramètres!$B$10,H11),"")) | K11: =IF(A11="","",SUMIFS(Commandes!$O:$O,Commandes!$C:$C,A11,Commandes!$P:$P,">0")) | L11: =IF(A11="","",IF(I11>IF(H11="",Paramètres!$B$10,H11),"Dépassement : livraison à valider par la direction",IF(J11>=0.8,"Proche du plafond","OK")))
I12: =IF(A12="","",SUMIFS(Commandes!$O:$O,Commandes!$C:$C,A12)) | J12: =IF(A12="","",IFERROR(I12/IF(H12="",Paramètres!$B$10,H12),"")) | K12: =IF(A12="","",SUMIFS(Commandes!$O:$O,Commandes!$C:$C,A12,Commandes!$P:$P,">0")) | L12: =IF(A12="","",IF(I12>IF(H12="",Paramètres!$B$10,H12),"Dépassement : livraison à valider par la direction",IF(J12>=0.8,"Proche du plafond","OK")))
I13: =IF(A13="","",SUMIFS(Commandes!$O:$O,Commandes!$C:$C,A13)) | J13: =IF(A13="","",IFERROR(I13/IF(H13="",Paramètres!$B$10,H13),"")) | K13: =IF(A13="","",SUMIFS(Commandes!$O:$O,Commandes!$C:$C,A13,Commandes!$P:$P,">0")) | L13: =IF(A13="","",IF(I13>IF(H13="",Paramètres!$B$10,H13),"Dépassement : livraison à valider par la direction",IF(J13>=0.8,"Proche du plafond","OK")))
I14: =IF(A14="","",SUMIFS(Commandes!$O:$O,Commandes!$C:$C,A14)) | J14: =IF(A14="","",IFERROR(I14/IF(H14="",Paramètres!$B$10,H14),"")) | K14: =IF(A14="","",SUMIFS(Commandes!$O:$O,Commandes!$C:$C,A14,Commandes!$P:$P,">0")) | L14: =IF(A14="","",IF(I14>IF(H14="",Paramètres!$B$10,H14),"Dépassement : livraison à valider par la direction",IF(J14>=0.8,"Proche du plafond","OK")))
I15: =IF(A15="","",SUMIFS(Commandes!$O:$O,Commandes!$C:$C,A15)) | J15: =IF(A15="","",IFERROR(I15/IF(H15="",Paramètres!$B$10,H15),"")) | K15: =IF(A15="","",SUMIFS(Commandes!$O:$O,Commandes!$C:$C,A15,Commandes!$P:$P,">0")) | L15: =IF(A15="","",IF(I15>IF(H15="",Paramètres!$B$10,H15),"Dépassement : livraison à valider par la direction",IF(J15>=0.8,"Proche du plafond","OK")))
I16: =IF(A16="","",SUMIFS(Commandes!$O:$O,Commandes!$C:$C,A16)) | J16: =IF(A16="","",IFERROR(I16/IF(H16="",Paramètres!$B$10,H16),"")) | K16: =IF(A16="","",SUMIFS(Commandes!$O:$O,Commandes!$C:$C,A16,Commandes!$P:$P,">0")) | L16: =IF(A16="","",IF(I16>IF(H16="",Paramètres!$B$10,H16),"Dépassement : livraison à valider par la direction",IF(J16>=0.8,"Proche du plafond","OK")))
I17: =IF(A17="","",SUMIFS(Commandes!$O:$O,Commandes!$C:$C,A17)) | J17: =IF(A17="","",IFERROR(I17/IF(H17="",Paramètres!$B$10,H17),"")) | K17: =IF(A17="","",SUMIFS(Commandes!$O:$O,Commandes!$C:$C,A17,Commandes!$P:$P,">0")) | L17: =IF(A17="","",IF(I17>IF(H17="",Paramètres!$B$10,H17),"Dépassement : livraison à valider par la direction",IF(J17>=0.8,"Proche du plafond","OK")))
I18: =IF(A18="","",SUMIFS(Commandes!$O:$O,Commandes!$C:$C,A18)) | J18: =IF(A18="","",IFERROR(I18/IF(H18="",Paramètres!$B$10,H18),"")) | K18: =IF(A18="","",SUMIFS(Commandes!$O:$O,Commandes!$C:$C,A18,Commandes!$P:$P,">0")) | L18: =IF(A18="","",IF(I18>IF(H18="",Paramètres!$B$10,H18),"Dépassement : livraison à valider par la direction",IF(J18>=0.8,"Proche du plafond","OK")))
... I101: =IF(A101="","",SUMIFS(Commandes!$O:$O,Commandes!$C:$C,A101)) | J101: =IF(A101="","",IFERROR(I101/IF(H101="",Paramètres!$B$10,H101),"")) | K101: =IF(A101="","",SUMIFS(Commandes!$O:$O,Commandes!$C:$C,A101,Commandes!$P:$P,">0")) | L101: =IF(A101="","",IF(I101>IF(H101="",Paramètres!$B$10,H101),"Dépassement : livraison à valider par la direction",IF(J101>=0.8,"Proche du plafond","OK")))

Sheet Commandes
A1: N° commande | B1: Date de commande | C1: Code revendeur | D1: Revendeur | E1: Produit | F1: Quantité | G1: Prix unitaire HT (FCFA) | H1: Montant HT (FCFA) | I1: Livraison promise le | J1: Livrée le | K1: Statut livraison | L1: Jours de retard livraison | M1: Échéance de paiement | N1: Montant payé (FCFA) | O1: Reste à payer (FCFA) | P1: Jours de retard de paiement | Q1: Statut paiement | R1: Action du jour | S1: Message préparé (WhatsApp) | T1: Validé par | U1: Relance envoyée le | V1: Notes
A2: C-0001 | B2: 46254 | C2: R001 | D2: =IF(C2="","",IFERROR(VLOOKUP(C2,Revendeurs!$A:$B,2,FALSE),"Code inconnu")) | E2: Chaise Ibiza | F2: 200 | G2: 4500 | H2: =IF(OR(F2="",G2=""),"",F2*G2) | I2: 46261 | J2: 46261 | K2: =IF(B2="","",IF(J2<>"","Livrée",IF(I2="","À planifier",IF(Paramètres!$B$4>I2+Paramètres!$B$8,"En retard","En cours")))) | L2: =IF(K2="En retard",Paramètres!$B$4-I2,"") | M2: =IF(OR(B2="",J2=""),"",J2+IFERROR(IF(VLOOKUP(C2,Revendeurs!$A:$G,7,FALSE)="",Paramètres!$B$9,VLOOKUP(C2,Revendeurs!$A:$G,7,FALSE)),Paramètres!$B$9)) | N2: 900000 | O2: =IF(H2="","",H2-N2) | P2: =IF(OR(M2="",O2=""),"",IF(O2<=0,0,MAX(0,Paramètres!$B$4-M2))) | Q2: =IF(H2="","",IF(O2<=0,"Payée",IF(M2="","Pas encore livrée",IF(P2=0,"Non échue",IF(P2>=Paramètres!$B$7,"Relance 3 : appel direction",IF(P2>=Paramètres!$B$6,"Relance 2",IF(P2>=Paramètres!$B$5,"Relance 1","Échue, relance à venir"))))))) | R2: =IF(B2="","",IF(U2=Paramètres!$B$4,"Relancé aujourd'hui",TRIM(IF(LEFT(Q2,7)="Relance",Q2&" ","")&IF(K2="En retard","· Prévenir du retard de livraison","")))) | S2: =IF(B2="","",IF(LEFT(Q2,9)="Relance 3","Bonjour "&D2&", nous revenons vers vous au sujet de la commande "&A2&" du "&TEXT(B2,"dd/mm/yyyy")&" : "&SUBSTITUTE(TEXT(O2,"#,##0"),","," ")&" FCFA restent à régler depuis le "&TEXT(M2,"dd/mm/yyyy")&". Notre responsable souhaite vous appeler pour convenir ensemble d'une solution. Quel moment vous arrange cette semaine ? "&Paramètres!$B$11&", "&Paramètres!$B$12,IF(LEFT(Q2,7)="Relance","Bonjour "&D2&", sauf erreur de notre part, la commande "&A2&" du "&TEXT(B2,"dd/mm/yyyy")&" ("&E2&") présente un reste à payer de "&SUBSTITUTE(TEXT(O2,"#,##0"),","," ")&" FCFA, échu depuis le "&TEXT(M2,"dd/mm/yyyy")&". Pouvez-vous nous indiquer la date de règlement prévue ? Si le paiement est déjà parti, merci de nous envoyer la preuve et ne tenez pas compte de ce message. "&Paramètres!$B$11&", "&Paramètres!$B$12,IF(K2="En retard","Bonjour "&D2&", votre commande "&A2&" ("&E2&", "&F2&" pièces) prévue le "&TEXT(I2,"dd/mm/yyyy")&" a pris du retard. Nous vous confirmons la nouvelle date de livraison dans la journée. Toutes nos excuses pour ce contretemps. "&Paramètres!$B$11&", "&Paramètres!$B$12,""))))
A3: C-0002 | B3: 46267 | C3: R002 | D3: =IF(C3="","",IFERROR(VLOOKUP(C3,Revendeurs!$A:$B,2,FALSE),"Code inconnu")) | E3: Bidon 20 L | F3: 120 | G3: 2800 | H3: =IF(OR(F3="",G3=""),"",F3*G3) | I3: 46274 | J3: 46275 | K3: =IF(B3="","",IF(J3<>"","Livrée",IF(I3="","À planifier",IF(Paramètres!$B$4>I3+Paramètres!$B$8,"En retard","En cours")))) | L3: =IF(K3="En retard",Paramètres!$B$4-I3,"") | M3: =IF(OR(B3="",J3=""),"",J3+IFERROR(IF(VLOOKUP(C3,Revendeurs!$A:$G,7,FALSE)="",Paramètres!$B$9,VLOOKUP(C3,Revendeurs!$A:$G,7,FALSE)),Paramètres!$B$9)) | N3: 0 | O3: =IF(H3="","",H3-N3) | P3: =IF(OR(M3="",O3=""),"",IF(O3<=0,0,MAX(0,Paramètres!$B$4-M3))) | Q3: =IF(H3="","",IF(O3<=0,"Payée",IF(M3="","Pas encore livrée",IF(P3=0,"Non échue",IF(P3>=Paramètres!$B$7,"Relance 3 : appel direction",IF(P3>=Paramètres!$B$6,"Relance 2",IF(P3>=Paramètres!$B$5,"Relance 1","Échue, relance à venir"))))))) | R3: =IF(B3="","",IF(U3=Paramètres!$B$4,"Relancé aujourd'hui",TRIM(IF(LEFT(Q3,7)="Relance",Q3&" ","")&IF(K3="En retard","· Prévenir du retard de livraison","")))) | S3: =IF(B3="","",IF(LEFT(Q3,9)="Relance 3","Bonjour "&D3&", nous revenons vers vous au sujet de la commande "&A3&" du "&TEXT(B3,"dd/mm/yyyy")&" : "&SUBSTITUTE(TEXT(O3,"#,##0"),","," ")&" FCFA restent à régler depuis le "&TEXT(M3,"dd/mm/yyyy")&". Notre responsable souhaite vous appeler pour convenir ensemble d'une solution. Quel moment vous arrange cette semaine ? "&Paramètres!$B$11&", "&Paramètres!$B$12,IF(LEFT(Q3,7)="Relance","Bonjour "&D3&", sauf erreur de notre part, la commande "&A3&" du "&TEXT(B3,"dd/mm/yyyy")&" ("&E3&") présente un reste à payer de "&SUBSTITUTE(TEXT(O3,"#,##0"),","," ")&" FCFA, échu depuis le "&TEXT(M3,"dd/mm/yyyy")&". Pouvez-vous nous indiquer la date de règlement prévue ? Si le paiement est déjà parti, merci de nous envoyer la preuve et ne tenez pas compte de ce message. "&Paramètres!$B$11&", "&Paramètres!$B$12,IF(K3="En retard","Bonjour "&D3&", votre commande "&A3&" ("&E3&", "&F3&" pièces) prévue le "&TEXT(I3,"dd/mm/yyyy")&" a pris du retard. Nous vous confirmons la nouvelle date de livraison dans la journée. Toutes nos excuses pour ce contretemps. "&Paramètres!$B$11&", "&Paramètres!$B$12,""))))
A4: C-0003 | B4: 46275 | C4: R003 | D4: =IF(C4="","",IFERROR(VLOOKUP(C4,Revendeurs!$A:$B,2,FALSE),"Code inconnu")) | E4: Poubelle à pédale | F4: 300 | G4: 3200 | H4: =IF(OR(F4="",G4=""),"",F4*G4) | I4: 46282 | J4: 46281 | K4: =IF(B4="","",IF(J4<>"","Livrée",IF(I4="","À planifier",IF(Paramètres!$B$4>I4+Paramètres!$B$8,"En retard","En cours")))) | L4: =IF(K4="En retard",Paramètres!$B$4-I4,"") | M4: =IF(OR(B4="",J4=""),"",J4+IFERROR(IF(VLOOKUP(C4,Revendeurs!$A:$G,7,FALSE)="",Paramètres!$B$9,VLOOKUP(C4,Revendeurs!$A:$G,7,FALSE)),Paramètres!$B$9)) | N4: 960000 | O4: =IF(H4="","",H4-N4) | P4: =IF(OR(M4="",O4=""),"",IF(O4<=0,0,MAX(0,Paramètres!$B$4-M4))) | Q4: =IF(H4="","",IF(O4<=0,"Payée",IF(M4="","Pas encore livrée",IF(P4=0,"Non échue",IF(P4>=Paramètres!$B$7,"Relance 3 : appel direction",IF(P4>=Paramètres!$B$6,"Relance 2",IF(P4>=Paramètres!$B$5,"Relance 1","Échue, relance à venir"))))))) | R4: =IF(B4="","",IF(U4=Paramètres!$B$4,"Relancé aujourd'hui",TRIM(IF(LEFT(Q4,7)="Relance",Q4&" ","")&IF(K4="En retard","· Prévenir du retard de livraison","")))) | S4: =IF(B4="","",IF(LEFT(Q4,9)="Relance 3","Bonjour "&D4&", nous revenons vers vous au sujet de la commande "&A4&" du "&TEXT(B4,"dd/mm/yyyy")&" : "&SUBSTITUTE(TEXT(O4,"#,##0"),","," ")&" FCFA restent à régler depuis le "&TEXT(M4,"dd/mm/yyyy")&". Notre responsable souhaite vous appeler pour convenir ensemble d'une solution. Quel moment vous arrange cette semaine ? "&Paramètres!$B$11&", "&Paramètres!$B$12,IF(LEFT(Q4,7)="Relance","Bonjour "&D4&", sauf erreur de notre part, la commande "&A4&" du "&TEXT(B4,"dd/mm/yyyy")&" ("&E4&") présente un reste à payer de "&SUBSTITUTE(TEXT(O4,"#,##0"),","," ")&" FCFA, échu depuis le "&TEXT(M4,"dd/mm/yyyy")&". Pouvez-vous nous indiquer la date de règlement prévue ? Si le paiement est déjà parti, merci de nous envoyer la preuve et ne tenez pas compte de ce message. "&Paramètres!$B$11&", "&Paramètres!$B$12,IF(K4="En retard","Bonjour "&D4&", votre commande "&A4&" ("&E4&", "&F4&" pièces) prévue le "&TEXT(I4,"dd/mm/yyyy")&" a pris du retard. Nous vous confirmons la nouvelle date de livraison dans la journée. Toutes nos excuses pour ce contretemps. "&Paramètres!$B$11&", "&Paramètres!$B$12,""))))
A5: C-0004 | B5: 46277 | C5: R001 | D5: =IF(C5="","",IFERROR(VLOOKUP(C5,Revendeurs!$A:$B,2,FALSE),"Code inconnu")) | E5: Table Choco | F5: 80 | G5: 12000 | H5: =IF(OR(F5="",G5=""),"",F5*G5) | I5: 46284 | J5: 46284 | K5: =IF(B5="","",IF(J5<>"","Livrée",IF(I5="","À planifier",IF(Paramètres!$B$4>I5+Paramètres!$B$8,"En retard","En cours")))) | L5: =IF(K5="En retard",Paramètres!$B$4-I5,"") | M5: =IF(OR(B5="",J5=""),"",J5+IFERROR(IF(VLOOKUP(C5,Revendeurs!$A:$G,7,FALSE)="",Paramètres!$B$9,VLOOKUP(C5,Revendeurs!$A:$G,7,FALSE)),Paramètres!$B$9)) | N5: 500000 | O5: =IF(H5="","",H5-N5) | P5: =IF(OR(M5="",O5=""),"",IF(O5<=0,0,MAX(0,Paramètres!$B$4-M5))) | Q5: =IF(H5="","",IF(O5<=0,"Payée",IF(M5="","Pas encore livrée",IF(P5=0,"Non échue",IF(P5>=Paramètres!$B$7,"Relance 3 : appel direction",IF(P5>=Paramètres!$B$6,"Relance 2",IF(P5>=Paramètres!$B$5,"Relance 1","Échue, relance à venir"))))))) | R5: =IF(B5="","",IF(U5=Paramètres!$B$4,"Relancé aujourd'hui",TRIM(IF(LEFT(Q5,7)="Relance",Q5&" ","")&IF(K5="En retard","· Prévenir du retard de livraison","")))) | S5: =IF(B5="","",IF(LEFT(Q5,9)="Relance 3","Bonjour "&D5&", nous revenons vers vous au sujet de la commande "&A5&" du "&TEXT(B5,"dd/mm/yyyy")&" : "&SUBSTITUTE(TEXT(O5,"#,##0"),","," ")&" FCFA restent à régler depuis le "&TEXT(M5,"dd/mm/yyyy")&". Notre responsable souhaite vous appeler pour convenir ensemble d'une solution. Quel moment vous arrange cette semaine ? "&Paramètres!$B$11&", "&Paramètres!$B$12,IF(LEFT(Q5,7)="Relance","Bonjour "&D5&", sauf erreur de notre part, la commande "&A5&" du "&TEXT(B5,"dd/mm/yyyy")&" ("&E5&") présente un reste à payer de "&SUBSTITUTE(TEXT(O5,"#,##0"),","," ")&" FCFA, échu depuis le "&TEXT(M5,"dd/mm/yyyy")&". Pouvez-vous nous indiquer la date de règlement prévue ? Si le paiement est déjà parti, merci de nous envoyer la preuve et ne tenez pas compte de ce message. "&Paramètres!$B$11&", "&Paramètres!$B$12,IF(K5="En retard","Bonjour "&D5&", votre commande "&A5&" ("&E5&", "&F5&" pièces) prévue le "&TEXT(I5,"dd/mm/yyyy")&" a pris du retard. Nous vous confirmons la nouvelle date de livraison dans la journée. Toutes nos excuses pour ce contretemps. "&Paramètres!$B$11&", "&Paramètres!$B$12,""))))
A6: C-0005 | B6: 46280 | C6: R004 | D6: =IF(C6="","",IFERROR(VLOOKUP(C6,Revendeurs!$A:$B,2,FALSE),"Code inconnu")) | E6: Bidon 5 L | F6: 480 | G6: 900 | H6: =IF(OR(F6="",G6=""),"",F6*G6) | I6: 46287 | J6: 46288 | K6: =IF(B6="","",IF(J6<>"","Livrée",IF(I6="","À planifier",IF(Paramètres!$B$4>I6+Paramètres!$B$8,"En retard","En cours")))) | L6: =IF(K6="En retard",Paramètres!$B$4-I6,"") | M6: =IF(OR(B6="",J6=""),"",J6+IFERROR(IF(VLOOKUP(C6,Revendeurs!$A:$G,7,FALSE)="",Paramètres!$B$9,VLOOKUP(C6,Revendeurs!$A:$G,7,FALSE)),Paramètres!$B$9)) | N6: 0 | O6: =IF(H6="","",H6-N6) | P6: =IF(OR(M6="",O6=""),"",IF(O6<=0,0,MAX(0,Paramètres!$B$4-M6))) | Q6: =IF(H6="","",IF(O6<=0,"Payée",IF(M6="","Pas encore livrée",IF(P6=0,"Non échue",IF(P6>=Paramètres!$B$7,"Relance 3 : appel direction",IF(P6>=Paramètres!$B$6,"Relance 2",IF(P6>=Paramètres!$B$5,"Relance 1","Échue, relance à venir"))))))) | R6: =IF(B6="","",IF(U6=Paramètres!$B$4,"Relancé aujourd'hui",TRIM(IF(LEFT(Q6,7)="Relance",Q6&" ","")&IF(K6="En retard","· Prévenir du retard de livraison","")))) | S6: =IF(B6="","",IF(LEFT(Q6,9)="Relance 3","Bonjour "&D6&", nous revenons vers vous au sujet de la commande "&A6&" du "&TEXT(B6,"dd/mm/yyyy")&" : "&SUBSTITUTE(TEXT(O6,"#,##0"),","," ")&" FCFA restent à régler depuis le "&TEXT(M6,"dd/mm/yyyy")&". Notre responsable souhaite vous appeler pour convenir ensemble d'une solution. Quel moment vous arrange cette semaine ? "&Paramètres!$B$11&", "&Paramètres!$B$12,IF(LEFT(Q6,7)="Relance","Bonjour "&D6&", sauf erreur de notre part, la commande "&A6&" du "&TEXT(B6,"dd/mm/yyyy")&" ("&E6&") présente un reste à payer de "&SUBSTITUTE(TEXT(O6,"#,##0"),","," ")&" FCFA, échu depuis le "&TEXT(M6,"dd/mm/yyyy")&". Pouvez-vous nous indiquer la date de règlement prévue ? Si le paiement est déjà parti, merci de nous envoyer la preuve et ne tenez pas compte de ce message. "&Paramètres!$B$11&", "&Paramètres!$B$12,IF(K6="En retard","Bonjour "&D6&", votre commande "&A6&" ("&E6&", "&F6&" pièces) prévue le "&TEXT(I6,"dd/mm/yyyy")&" a pris du retard. Nous vous confirmons la nouvelle date de livraison dans la journée. Toutes nos excuses pour ce contretemps. "&Paramètres!$B$11&", "&Paramètres!$B$12,""))))
A7: C-0006 | B7: 46290 | C7: R005 | D7: =IF(C7="","",IFERROR(VLOOKUP(C7,Revendeurs!$A:$B,2,FALSE),"Code inconnu")) | E7: Cuve de stockage (capacité à préciser) | F7: 10 | G7: 150000 | H7: =IF(OR(F7="",G7=""),"",F7*G7) | I7: 46297 | J7: 46298 | K7: =IF(B7="","",IF(J7<>"","Livrée",IF(I7="","À planifier",IF(Paramètres!$B$4>I7+Paramètres!$B$8,"En retard","En cours")))) | L7: =IF(K7="En retard",Paramètres!$B$4-I7,"") | M7: =IF(OR(B7="",J7=""),"",J7+IFERROR(IF(VLOOKUP(C7,Revendeurs!$A:$G,7,FALSE)="",Paramètres!$B$9,VLOOKUP(C7,Revendeurs!$A:$G,7,FALSE)),Paramètres!$B$9)) | N7: 0 | O7: =IF(H7="","",H7-N7) | P7: =IF(OR(M7="",O7=""),"",IF(O7<=0,0,MAX(0,Paramètres!$B$4-M7))) | Q7: =IF(H7="","",IF(O7<=0,"Payée",IF(M7="","Pas encore livrée",IF(P7=0,"Non échue",IF(P7>=Paramètres!$B$7,"Relance 3 : appel direction",IF(P7>=Paramètres!$B$6,"Relance 2",IF(P7>=Paramètres!$B$5,"Relance 1","Échue, relance à venir"))))))) | R7: =IF(B7="","",IF(U7=Paramètres!$B$4,"Relancé aujourd'hui",TRIM(IF(LEFT(Q7,7)="Relance",Q7&" ","")&IF(K7="En retard","· Prévenir du retard de livraison","")))) | S7: =IF(B7="","",IF(LEFT(Q7,9)="Relance 3","Bonjour "&D7&", nous revenons vers vous au sujet de la commande "&A7&" du "&TEXT(B7,"dd/mm/yyyy")&" : "&SUBSTITUTE(TEXT(O7,"#,##0"),","," ")&" FCFA restent à régler depuis le "&TEXT(M7,"dd/mm/yyyy")&". Notre responsable souhaite vous appeler pour convenir ensemble d'une solution. Quel moment vous arrange cette semaine ? "&Paramètres!$B$11&", "&Paramètres!$B$12,IF(LEFT(Q7,7)="Relance","Bonjour "&D7&", sauf erreur de notre part, la commande "&A7&" du "&TEXT(B7,"dd/mm/yyyy")&" ("&E7&") présente un reste à payer de "&SUBSTITUTE(TEXT(O7,"#,##0"),","," ")&" FCFA, échu depuis le "&TEXT(M7,"dd/mm/yyyy")&". Pouvez-vous nous indiquer la date de règlement prévue ? Si le paiement est déjà parti, merci de nous envoyer la preuve et ne tenez pas compte de ce message. "&Paramètres!$B$11&", "&Paramètres!$B$12,IF(K7="En retard","Bonjour "&D7&", votre commande "&A7&" ("&E7&", "&F7&" pièces) prévue le "&TEXT(I7,"dd/mm/yyyy")&" a pris du retard. Nous vous confirmons la nouvelle date de livraison dans la journée. Toutes nos excuses pour ce contretemps. "&Paramètres!$B$11&", "&Paramètres!$B$12,""))))
A8: C-0007 | B8: 46300 | C8: R002 | D8: =IF(C8="","",IFERROR(VLOOKUP(C8,Revendeurs!$A:$B,2,FALSE),"Code inconnu")) | E8: Arrosoir 15 L | F8: 60 | G8: 2500 | H8: =IF(OR(F8="",G8=""),"",F8*G8) | I8: 46307 | J8: 46307 | K8: =IF(B8="","",IF(J8<>"","Livrée",IF(I8="","À planifier",IF(Paramètres!$B$4>I8+Paramètres!$B$8,"En retard","En cours")))) | L8: =IF(K8="En retard",Paramètres!$B$4-I8,"") | M8: =IF(OR(B8="",J8=""),"",J8+IFERROR(IF(VLOOKUP(C8,Revendeurs!$A:$G,7,FALSE)="",Paramètres!$B$9,VLOOKUP(C8,Revendeurs!$A:$G,7,FALSE)),Paramètres!$B$9)) | N8: 0 | O8: =IF(H8="","",H8-N8) | P8: =IF(OR(M8="",O8=""),"",IF(O8<=0,0,MAX(0,Paramètres!$B$4-M8))) | Q8: =IF(H8="","",IF(O8<=0,"Payée",IF(M8="","Pas encore livrée",IF(P8=0,"Non échue",IF(P8>=Paramètres!$B$7,"Relance 3 : appel direction",IF(P8>=Paramètres!$B$6,"Relance 2",IF(P8>=Paramètres!$B$5,"Relance 1","Échue, relance à venir"))))))) | R8: =IF(B8="","",IF(U8=Paramètres!$B$4,"Relancé aujourd'hui",TRIM(IF(LEFT(Q8,7)="Relance",Q8&" ","")&IF(K8="En retard","· Prévenir du retard de livraison","")))) | S8: =IF(B8="","",IF(LEFT(Q8,9)="Relance 3","Bonjour "&D8&", nous revenons vers vous au sujet de la commande "&A8&" du "&TEXT(B8,"dd/mm/yyyy")&" : "&SUBSTITUTE(TEXT(O8,"#,##0"),","," ")&" FCFA restent à régler depuis le "&TEXT(M8,"dd/mm/yyyy")&". Notre responsable souhaite vous appeler pour convenir ensemble d'une solution. Quel moment vous arrange cette semaine ? "&Paramètres!$B$11&", "&Paramètres!$B$12,IF(LEFT(Q8,7)="Relance","Bonjour "&D8&", sauf erreur de notre part, la commande "&A8&" du "&TEXT(B8,"dd/mm/yyyy")&" ("&E8&") présente un reste à payer de "&SUBSTITUTE(TEXT(O8,"#,##0"),","," ")&" FCFA, échu depuis le "&TEXT(M8,"dd/mm/yyyy")&". Pouvez-vous nous indiquer la date de règlement prévue ? Si le paiement est déjà parti, merci de nous envoyer la preuve et ne tenez pas compte de ce message. "&Paramètres!$B$11&", "&Paramètres!$B$12,IF(K8="En retard","Bonjour "&D8&", votre commande "&A8&" ("&E8&", "&F8&" pièces) prévue le "&TEXT(I8,"dd/mm/yyyy")&" a pris du retard. Nous vous confirmons la nouvelle date de livraison dans la journée. Toutes nos excuses pour ce contretemps. "&Paramètres!$B$11&", "&Paramètres!$B$12,""))))
A9: C-0008 | B9: 46307 | C9: R003 | D9: =IF(C9="","",IFERROR(VLOOKUP(C9,Revendeurs!$A:$B,2,FALSE),"Code inconnu")) | E9: Armoire de rangement | F9: 40 | G9: 25000 | H9: =IF(OR(F9="",G9=""),"",F9*G9) | I9: 46315 | K9: =IF(B9="","",IF(J9<>"","Livrée",IF(I9="","À planifier",IF(Paramètres!$B$4>I9+Paramètres!$B$8,"En retard","En cours")))) | L9: =IF(K9="En retard",Paramètres!$B$4-I9,"") | M9: =IF(OR(B9="",J9=""),"",J9+IFERROR(IF(VLOOKUP(C9,Revendeurs!$A:$G,7,FALSE)="",Paramètres!$B$9,VLOOKUP(C9,Revendeurs!$A:$G,7,FALSE)),Paramètres!$B$9)) | N9: 0 | O9: =IF(H9="","",H9-N9) | P9: =IF(OR(M9="",O9=""),"",IF(O9<=0,0,MAX(0,Paramètres!$B$4-M9))) | Q9: =IF(H9="","",IF(O9<=0,"Payée",IF(M9="","Pas encore livrée",IF(P9=0,"Non échue",IF(P9>=Paramètres!$B$7,"Relance 3 : appel direction",IF(P9>=Paramètres!$B$6,"Relance 2",IF(P9>=Paramètres!$B$5,"Relance 1","Échue, relance à venir"))))))) | R9: =IF(B9="","",IF(U9=Paramètres!$B$4,"Relancé aujourd'hui",TRIM(IF(LEFT(Q9,7)="Relance",Q9&" ","")&IF(K9="En retard","· Prévenir du retard de livraison","")))) | S9: =IF(B9="","",IF(LEFT(Q9,9)="Relance 3","Bonjour "&D9&", nous revenons vers vous au sujet de la commande "&A9&" du "&TEXT(B9,"dd/mm/yyyy")&" : "&SUBSTITUTE(TEXT(O9,"#,##0"),","," ")&" FCFA restent à régler depuis le "&TEXT(M9,"dd/mm/yyyy")&". Notre responsable souhaite vous appeler pour convenir ensemble d'une solution. Quel moment vous arrange cette semaine ? "&Paramètres!$B$11&", "&Paramètres!$B$12,IF(LEFT(Q9,7)="Relance","Bonjour "&D9&", sauf erreur de notre part, la commande "&A9&" du "&TEXT(B9,"dd/mm/yyyy")&" ("&E9&") présente un reste à payer de "&SUBSTITUTE(TEXT(O9,"#,##0"),","," ")&" FCFA, échu depuis le "&TEXT(M9,"dd/mm/yyyy")&". Pouvez-vous nous indiquer la date de règlement prévue ? Si le paiement est déjà parti, merci de nous envoyer la preuve et ne tenez pas compte de ce message. "&Paramètres!$B$11&", "&Paramètres!$B$12,IF(K9="En retard","Bonjour "&D9&", votre commande "&A9&" ("&E9&", "&F9&" pièces) prévue le "&TEXT(I9,"dd/mm/yyyy")&" a pris du retard. Nous vous confirmons la nouvelle date de livraison dans la journée. Toutes nos excuses pour ce contretemps. "&Paramètres!$B$11&", "&Paramètres!$B$12,""))))
A10: C-0009 | B10: 46310 | C10: R005 | D10: =IF(C10="","",IFERROR(VLOOKUP(C10,Revendeurs!$A:$B,2,FALSE),"Code inconnu")) | E10: Fosse septique (modèle à préciser) | F10: 6 | G10: 250000 | H10: =IF(OR(F10="",G10=""),"",F10*G10) | I10: 46317 | K10: =IF(B10="","",IF(J10<>"","Livrée",IF(I10="","À planifier",IF(Paramètres!$B$4>I10+Paramètres!$B$8,"En retard","En cours")))) | L10: =IF(K10="En retard",Paramètres!$B$4-I10,"") | M10: =IF(OR(B10="",J10=""),"",J10+IFERROR(IF(VLOOKUP(C10,Revendeurs!$A:$G,7,FALSE)="",Paramètres!$B$9,VLOOKUP(C10,Revendeurs!$A:$G,7,FALSE)),Paramètres!$B$9)) | N10: 0 | O10: =IF(H10="","",H10-N10) | P10: =IF(OR(M10="",O10=""),"",IF(O10<=0,0,MAX(0,Paramètres!$B$4-M10))) | Q10: =IF(H10="","",IF(O10<=0,"Payée",IF(M10="","Pas encore livrée",IF(P10=0,"Non échue",IF(P10>=Paramètres!$B$7,"Relance 3 : appel direction",IF(P10>=Paramètres!$B$6,"Relance 2",IF(P10>=Paramètres!$B$5,"Relance 1","Échue, relance à venir"))))))) | R10: =IF(B10="","",IF(U10=Paramètres!$B$4,"Relancé aujourd'hui",TRIM(IF(LEFT(Q10,7)="Relance",Q10&" ","")&IF(K10="En retard","· Prévenir du retard de livraison","")))) | S10: =IF(B10="","",IF(LEFT(Q10,9)="Relance 3","Bonjour "&D10&", nous revenons vers vous au sujet de la commande "&A10&" du "&TEXT(B10,"dd/mm/yyyy")&" : "&SUBSTITUTE(TEXT(O10,"#,##0"),","," ")&" FCFA restent à régler depuis le "&TEXT(M10,"dd/mm/yyyy")&". Notre responsable souhaite vous appeler pour convenir ensemble d'une solution. Quel moment vous arrange cette semaine ? "&Paramètres!$B$11&", "&Paramètres!$B$12,IF(LEFT(Q10,7)="Relance","Bonjour "&D10&", sauf erreur de notre part, la commande "&A10&" du "&TEXT(B10,"dd/mm/yyyy")&" ("&E10&") présente un reste à payer de "&SUBSTITUTE(TEXT(O10,"#,##0"),","," ")&" FCFA, échu depuis le "&TEXT(M10,"dd/mm/yyyy")&". Pouvez-vous nous indiquer la date de règlement prévue ? Si le paiement est déjà parti, merci de nous envoyer la preuve et ne tenez pas compte de ce message. "&Paramètres!$B$11&", "&Paramètres!$B$12,IF(K10="En retard","Bonjour "&D10&", votre commande "&A10&" ("&E10&", "&F10&" pièces) prévue le "&TEXT(I10,"dd/mm/yyyy")&" a pris du retard. Nous vous confirmons la nouvelle date de livraison dans la journée. Toutes nos excuses pour ce contretemps. "&Paramètres!$B$11&", "&Paramètres!$B$12,""))))
A11: C-0010 | B11: 46315 | C11: R001 | D11: =IF(C11="","",IFERROR(VLOOKUP(C11,Revendeurs!$A:$B,2,FALSE),"Code inconnu")) | E11: Chaise Ibiza | F11: 300 | G11: 4500 | H11: =IF(OR(F11="",G11=""),"",F11*G11) | I11: 46325 | K11: =IF(B11="","",IF(J11<>"","Livrée",IF(I11="","À planifier",IF(Paramètres!$B$4>I11+Paramètres!$B$8,"En retard","En cours")))) | L11: =IF(K11="En retard",Paramètres!$B$4-I11,"") | M11: =IF(OR(B11="",J11=""),"",J11+IFERROR(IF(VLOOKUP(C11,Revendeurs!$A:$G,7,FALSE)="",Paramètres!$B$9,VLOOKUP(C11,Revendeurs!$A:$G,7,FALSE)),Paramètres!$B$9)) | N11: 0 | O11: =IF(H11="","",H11-N11) | P11: =IF(OR(M11="",O11=""),"",IF(O11<=0,0,MAX(0,Paramètres!$B$4-M11))) | Q11: =IF(H11="","",IF(O11<=0,"Payée",IF(M11="","Pas encore livrée",IF(P11=0,"Non échue",IF(P11>=Paramètres!$B$7,"Relance 3 : appel direction",IF(P11>=Paramètres!$B$6,"Relance 2",IF(P11>=Paramètres!$B$5,"Relance 1","Échue, relance à venir"))))))) | R11: =IF(B11="","",IF(U11=Paramètres!$B$4,"Relancé aujourd'hui",TRIM(IF(LEFT(Q11,7)="Relance",Q11&" ","")&IF(K11="En retard","· Prévenir du retard de livraison","")))) | S11: =IF(B11="","",IF(LEFT(Q11,9)="Relance 3","Bonjour "&D11&", nous revenons vers vous au sujet de la commande "&A11&" du "&TEXT(B11,"dd/mm/yyyy")&" : "&SUBSTITUTE(TEXT(O11,"#,##0"),","," ")&" FCFA restent à régler depuis le "&TEXT(M11,"dd/mm/yyyy")&". Notre responsable souhaite vous appeler pour convenir ensemble d'une solution. Quel moment vous arrange cette semaine ? "&Paramètres!$B$11&", "&Paramètres!$B$12,IF(LEFT(Q11,7)="Relance","Bonjour "&D11&", sauf erreur de notre part, la commande "&A11&" du "&TEXT(B11,"dd/mm/yyyy")&" ("&E11&") présente un reste à payer de "&SUBSTITUTE(TEXT(O11,"#,##0"),","," ")&" FCFA, échu depuis le "&TEXT(M11,"dd/mm/yyyy")&". Pouvez-vous nous indiquer la date de règlement prévue ? Si le paiement est déjà parti, merci de nous envoyer la preuve et ne tenez pas compte de ce message. "&Paramètres!$B$11&", "&Paramètres!$B$12,IF(K11="En retard","Bonjour "&D11&", votre commande "&A11&" ("&E11&", "&F11&" pièces) prévue le "&TEXT(I11,"dd/mm/yyyy")&" a pris du retard. Nous vous confirmons la nouvelle date de livraison dans la journée. Toutes nos excuses pour ce contretemps. "&Paramètres!$B$11&", "&Paramètres!$B$12,""))))
A12: C-0011 | B12: 46317 | C12: R004 | D12: =IF(C12="","",IFERROR(VLOOKUP(C12,Revendeurs!$A:$B,2,FALSE),"Code inconnu")) | E12: Bidon 25 L | F12: 50 | G12: 3500 | H12: =IF(OR(F12="",G12=""),"",F12*G12) | I12: 46324 | K12: =IF(B12="","",IF(J12<>"","Livrée",IF(I12="","À planifier",IF(Paramètres!$B$4>I12+Paramètres!$B$8,"En retard","En cours")))) | L12: =IF(K12="En retard",Paramètres!$B$4-I12,"") | M12: =IF(OR(B12="",J12=""),"",J12+IFERROR(IF(VLOOKUP(C12,Revendeurs!$A:$G,7,FALSE)="",Paramètres!$B$9,VLOOKUP(C12,Revendeurs!$A:$G,7,FALSE)),Paramètres!$B$9)) | N12: 0 | O12: =IF(H12="","",H12-N12) | P12: =IF(OR(M12="",O12=""),"",IF(O12<=0,0,MAX(0,Paramètres!$B$4-M12))) | Q12: =IF(H12="","",IF(O12<=0,"Payée",IF(M12="","Pas encore livrée",IF(P12=0,"Non échue",IF(P12>=Paramètres!$B$7,"Relance 3 : appel direction",IF(P12>=Paramètres!$B$6,"Relance 2",IF(P12>=Paramètres!$B$5,"Relance 1","Échue, relance à venir"))))))) | R12: =IF(B12="","",IF(U12=Paramètres!$B$4,"Relancé aujourd'hui",TRIM(IF(LEFT(Q12,7)="Relance",Q12&" ","")&IF(K12="En retard","· Prévenir du retard de livraison","")))) | S12: =IF(B12="","",IF(LEFT(Q12,9)="Relance 3","Bonjour "&D12&", nous revenons vers vous au sujet de la commande "&A12&" du "&TEXT(B12,"dd/mm/yyyy")&" : "&SUBSTITUTE(TEXT(O12,"#,##0"),","," ")&" FCFA restent à régler depuis le "&TEXT(M12,"dd/mm/yyyy")&". Notre responsable souhaite vous appeler pour convenir ensemble d'une solution. Quel moment vous arrange cette semaine ? "&Paramètres!$B$11&", "&Paramètres!$B$12,IF(LEFT(Q12,7)="Relance","Bonjour "&D12&", sauf erreur de notre part, la commande "&A12&" du "&TEXT(B12,"dd/mm/yyyy")&" ("&E12&") présente un reste à payer de "&SUBSTITUTE(TEXT(O12,"#,##0"),","," ")&" FCFA, échu depuis le "&TEXT(M12,"dd/mm/yyyy")&". Pouvez-vous nous indiquer la date de règlement prévue ? Si le paiement est déjà parti, merci de nous envoyer la preuve et ne tenez pas compte de ce message. "&Paramètres!$B$11&", "&Paramètres!$B$12,IF(K12="En retard","Bonjour "&D12&", votre commande "&A12&" ("&E12&", "&F12&" pièces) prévue le "&TEXT(I12,"dd/mm/yyyy")&" a pris du retard. Nous vous confirmons la nouvelle date de livraison dans la journée. Toutes nos excuses pour ce contretemps. "&Paramètres!$B$11&", "&Paramètres!$B$12,""))))
A13: C-0012 | B13: 46321 | C13: R002 | D13: =IF(C13="","",IFERROR(VLOOKUP(C13,Revendeurs!$A:$B,2,FALSE),"Code inconnu")) | E13: Tube orange (rouleau) | F13: 30 | G13: 20000 | H13: =IF(OR(F13="",G13=""),"",F13*G13) | I13: 46328 | K13: =IF(B13="","",IF(J13<>"","Livrée",IF(I13="","À planifier",IF(Paramètres!$B$4>I13+Paramètres!$B$8,"En retard","En cours")))) | L13: =IF(K13="En retard",Paramètres!$B$4-I13,"") | M13: =IF(OR(B13="",J13=""),"",J13+IFERROR(IF(VLOOKUP(C13,Revendeurs!$A:$G,7,FALSE)="",Paramètres!$B$9,VLOOKUP(C13,Revendeurs!$A:$G,7,FALSE)),Paramètres!$B$9)) | N13: 0 | O13: =IF(H13="","",H13-N13) | P13: =IF(OR(M13="",O13=""),"",IF(O13<=0,0,MAX(0,Paramètres!$B$4-M13))) | Q13: =IF(H13="","",IF(O13<=0,"Payée",IF(M13="","Pas encore livrée",IF(P13=0,"Non échue",IF(P13>=Paramètres!$B$7,"Relance 3 : appel direction",IF(P13>=Paramètres!$B$6,"Relance 2",IF(P13>=Paramètres!$B$5,"Relance 1","Échue, relance à venir"))))))) | R13: =IF(B13="","",IF(U13=Paramètres!$B$4,"Relancé aujourd'hui",TRIM(IF(LEFT(Q13,7)="Relance",Q13&" ","")&IF(K13="En retard","· Prévenir du retard de livraison","")))) | S13: =IF(B13="","",IF(LEFT(Q13,9)="Relance 3","Bonjour "&D13&", nous revenons vers vous au sujet de la commande "&A13&" du "&TEXT(B13,"dd/mm/yyyy")&" : "&SUBSTITUTE(TEXT(O13,"#,##0"),","," ")&" FCFA restent à régler depuis le "&TEXT(M13,"dd/mm/yyyy")&". Notre responsable souhaite vous appeler pour convenir ensemble d'une solution. Quel moment vous arrange cette semaine ? "&Paramètres!$B$11&", "&Paramètres!$B$12,IF(LEFT(Q13,7)="Relance","Bonjour "&D13&", sauf erreur de notre part, la commande "&A13&" du "&TEXT(B13,"dd/mm/yyyy")&" ("&E13&") présente un reste à payer de "&SUBSTITUTE(TEXT(O13,"#,##0"),","," ")&" FCFA, échu depuis le "&TEXT(M13,"dd/mm/yyyy")&". Pouvez-vous nous indiquer la date de règlement prévue ? Si le paiement est déjà parti, merci de nous envoyer la preuve et ne tenez pas compte de ce message. "&Paramètres!$B$11&", "&Paramètres!$B$12,IF(K13="En retard","Bonjour "&D13&", votre commande "&A13&" ("&E13&", "&F13&" pièces) prévue le "&TEXT(I13,"dd/mm/yyyy")&" a pris du retard. Nous vous confirmons la nouvelle date de livraison dans la journée. Toutes nos excuses pour ce contretemps. "&Paramètres!$B$11&", "&Paramètres!$B$12,""))))
D14: =IF(C14="","",IFERROR(VLOOKUP(C14,Revendeurs!$A:$B,2,FALSE),"Code inconnu")) | H14: =IF(OR(F14="",G14=""),"",F14*G14) | K14: =IF(B14="","",IF(J14<>"","Livrée",IF(I14="","À planifier",IF(Paramètres!$B$4>I14+Paramètres!$B$8,"En retard","En cours")))) | L14: =IF(K14="En retard",Paramètres!$B$4-I14,"") | M14: =IF(OR(B14="",J14=""),"",J14+IFERROR(IF(VLOOKUP(C14,Revendeurs!$A:$G,7,FALSE)="",Paramètres!$B$9,VLOOKUP(C14,Revendeurs!$A:$G,7,FALSE)),Paramètres!$B$9)) | O14: =IF(H14="","",H14-N14) | P14: =IF(OR(M14="",O14=""),"",IF(O14<=0,0,MAX(0,Paramètres!$B$4-M14))) | Q14: =IF(H14="","",IF(O14<=0,"Payée",IF(M14="","Pas encore livrée",IF(P14=0,"Non échue",IF(P14>=Paramètres!$B$7,"Relance 3 : appel direction",IF(P14>=Paramètres!$B$6,"Relance 2",IF(P14>=Paramètres!$B$5,"Relance 1","Échue, relance à venir"))))))) | R14: =IF(B14="","",IF(U14=Paramètres!$B$4,"Relancé aujourd'hui",TRIM(IF(LEFT(Q14,7)="Relance",Q14&" ","")&IF(K14="En retard","· Prévenir du retard de livraison","")))) | S14: =IF(B14="","",IF(LEFT(Q14,9)="Relance 3","Bonjour "&D14&", nous revenons vers vous au sujet de la commande "&A14&" du "&TEXT(B14,"dd/mm/yyyy")&" : "&SUBSTITUTE(TEXT(O14,"#,##0"),","," ")&" FCFA restent à régler depuis le "&TEXT(M14,"dd/mm/yyyy")&". Notre responsable souhaite vous appeler pour convenir ensemble d'une solution. Quel moment vous arrange cette semaine ? "&Paramètres!$B$11&", "&Paramètres!$B$12,IF(LEFT(Q14,7)="Relance","Bonjour "&D14&", sauf erreur de notre part, la commande "&A14&" du "&TEXT(B14,"dd/mm/yyyy")&" ("&E14&") présente un reste à payer de "&SUBSTITUTE(TEXT(O14,"#,##0"),","," ")&" FCFA, échu depuis le "&TEXT(M14,"dd/mm/yyyy")&". Pouvez-vous nous indiquer la date de règlement prévue ? Si le paiement est déjà parti, merci de nous envoyer la preuve et ne tenez pas compte de ce message. "&Paramètres!$B$11&", "&Paramètres!$B$12,IF(K14="En retard","Bonjour "&D14&", votre commande "&A14&" ("&E14&", "&F14&" pièces) prévue le "&TEXT(I14,"dd/mm/yyyy")&" a pris du retard. Nous vous confirmons la nouvelle date de livraison dans la journée. Toutes nos excuses pour ce contretemps. "&Paramètres!$B$11&", "&Paramètres!$B$12,""))))
D15: =IF(C15="","",IFERROR(VLOOKUP(C15,Revendeurs!$A:$B,2,FALSE),"Code inconnu")) | H15: =IF(OR(F15="",G15=""),"",F15*G15) | K15: =IF(B15="","",IF(J15<>"","Livrée",IF(I15="","À planifier",IF(Paramètres!$B$4>I15+Paramètres!$B$8,"En retard","En cours")))) | L15: =IF(K15="En retard",Paramètres!$B$4-I15,"") | M15: =IF(OR(B15="",J15=""),"",J15+IFERROR(IF(VLOOKUP(C15,Revendeurs!$A:$G,7,FALSE)="",Paramètres!$B$9,VLOOKUP(C15,Revendeurs!$A:$G,7,FALSE)),Paramètres!$B$9)) | O15: =IF(H15="","",H15-N15) | P15: =IF(OR(M15="",O15=""),"",IF(O15<=0,0,MAX(0,Paramètres!$B$4-M15))) | Q15: =IF(H15="","",IF(O15<=0,"Payée",IF(M15="","Pas encore livrée",IF(P15=0,"Non échue",IF(P15>=Paramètres!$B$7,"Relance 3 : appel direction",IF(P15>=Paramètres!$B$6,"Relance 2",IF(P15>=Paramètres!$B$5,"Relance 1","Échue, relance à venir"))))))) | R15: =IF(B15="","",IF(U15=Paramètres!$B$4,"Relancé aujourd'hui",TRIM(IF(LEFT(Q15,7)="Relance",Q15&" ","")&IF(K15="En retard","· Prévenir du retard de livraison","")))) | S15: =IF(B15="","",IF(LEFT(Q15,9)="Relance 3","Bonjour "&D15&", nous revenons vers vous au sujet de la commande "&A15&" du "&TEXT(B15,"dd/mm/yyyy")&" : "&SUBSTITUTE(TEXT(O15,"#,##0"),","," ")&" FCFA restent à régler depuis le "&TEXT(M15,"dd/mm/yyyy")&". Notre responsable souhaite vous appeler pour convenir ensemble d'une solution. Quel moment vous arrange cette semaine ? "&Paramètres!$B$11&", "&Paramètres!$B$12,IF(LEFT(Q15,7)="Relance","Bonjour "&D15&", sauf erreur de notre part, la commande "&A15&" du "&TEXT(B15,"dd/mm/yyyy")&" ("&E15&") présente un reste à payer de "&SUBSTITUTE(TEXT(O15,"#,##0"),","," ")&" FCFA, échu depuis le "&TEXT(M15,"dd/mm/yyyy")&". Pouvez-vous nous indiquer la date de règlement prévue ? Si le paiement est déjà parti, merci de nous envoyer la preuve et ne tenez pas compte de ce message. "&Paramètres!$B$11&", "&Paramètres!$B$12,IF(K15="En retard","Bonjour "&D15&", votre commande "&A15&" ("&E15&", "&F15&" pièces) prévue le "&TEXT(I15,"dd/mm/yyyy")&" a pris du retard. Nous vous confirmons la nouvelle date de livraison dans la journée. Toutes nos excuses pour ce contretemps. "&Paramètres!$B$11&", "&Paramètres!$B$12,""))))
D16: =IF(C16="","",IFERROR(VLOOKUP(C16,Revendeurs!$A:$B,2,FALSE),"Code inconnu")) | H16: =IF(OR(F16="",G16=""),"",F16*G16) | K16: =IF(B16="","",IF(J16<>"","Livrée",IF(I16="","À planifier",IF(Paramètres!$B$4>I16+Paramètres!$B$8,"En retard","En cours")))) | L16: =IF(K16="En retard",Paramètres!$B$4-I16,"") | M16: =IF(OR(B16="",J16=""),"",J16+IFERROR(IF(VLOOKUP(C16,Revendeurs!$A:$G,7,FALSE)="",Paramètres!$B$9,VLOOKUP(C16,Revendeurs!$A:$G,7,FALSE)),Paramètres!$B$9)) | O16: =IF(H16="","",H16-N16) | P16: =IF(OR(M16="",O16=""),"",IF(O16<=0,0,MAX(0,Paramètres!$B$4-M16))) | Q16: =IF(H16="","",IF(O16<=0,"Payée",IF(M16="","Pas encore livrée",IF(P16=0,"Non échue",IF(P16>=Paramètres!$B$7,"Relance 3 : appel direction",IF(P16>=Paramètres!$B$6,"Relance 2",IF(P16>=Paramètres!$B$5,"Relance 1","Échue, relance à venir"))))))) | R16: =IF(B16="","",IF(U16=Paramètres!$B$4,"Relancé aujourd'hui",TRIM(IF(LEFT(Q16,7)="Relance",Q16&" ","")&IF(K16="En retard","· Prévenir du retard de livraison","")))) | S16: =IF(B16="","",IF(LEFT(Q16,9)="Relance 3","Bonjour "&D16&", nous revenons vers vous au sujet de la commande "&A16&" du "&TEXT(B16,"dd/mm/yyyy")&" : "&SUBSTITUTE(TEXT(O16,"#,##0"),","," ")&" FCFA restent à régler depuis le "&TEXT(M16,"dd/mm/yyyy")&". Notre responsable souhaite vous appeler pour convenir ensemble d'une solution. Quel moment vous arrange cette semaine ? "&Paramètres!$B$11&", "&Paramètres!$B$12,IF(LEFT(Q16,7)="Relance","Bonjour "&D16&", sauf erreur de notre part, la commande "&A16&" du "&TEXT(B16,"dd/mm/yyyy")&" ("&E16&") présente un reste à payer de "&SUBSTITUTE(TEXT(O16,"#,##0"),","," ")&" FCFA, échu depuis le "&TEXT(M16,"dd/mm/yyyy")&". Pouvez-vous nous indiquer la date de règlement prévue ? Si le paiement est déjà parti, merci de nous envoyer la preuve et ne tenez pas compte de ce message. "&Paramètres!$B$11&", "&Paramètres!$B$12,IF(K16="En retard","Bonjour "&D16&", votre commande "&A16&" ("&E16&", "&F16&" pièces) prévue le "&TEXT(I16,"dd/mm/yyyy")&" a pris du retard. Nous vous confirmons la nouvelle date de livraison dans la journée. Toutes nos excuses pour ce contretemps. "&Paramètres!$B$11&", "&Paramètres!$B$12,""))))
D17: =IF(C17="","",IFERROR(VLOOKUP(C17,Revendeurs!$A:$B,2,FALSE),"Code inconnu")) | H17: =IF(OR(F17="",G17=""),"",F17*G17) | K17: =IF(B17="","",IF(J17<>"","Livrée",IF(I17="","À planifier",IF(Paramètres!$B$4>I17+Paramètres!$B$8,"En retard","En cours")))) | L17: =IF(K17="En retard",Paramètres!$B$4-I17,"") | M17: =IF(OR(B17="",J17=""),"",J17+IFERROR(IF(VLOOKUP(C17,Revendeurs!$A:$G,7,FALSE)="",Paramètres!$B$9,VLOOKUP(C17,Revendeurs!$A:$G,7,FALSE)),Paramètres!$B$9)) | O17: =IF(H17="","",H17-N17) | P17: =IF(OR(M17="",O17=""),"",IF(O17<=0,0,MAX(0,Paramètres!$B$4-M17))) | Q17: =IF(H17="","",IF(O17<=0,"Payée",IF(M17="","Pas encore livrée",IF(P17=0,"Non échue",IF(P17>=Paramètres!$B$7,"Relance 3 : appel direction",IF(P17>=Paramètres!$B$6,"Relance 2",IF(P17>=Paramètres!$B$5,"Relance 1","Échue, relance à venir"))))))) | R17: =IF(B17="","",IF(U17=Paramètres!$B$4,"Relancé aujourd'hui",TRIM(IF(LEFT(Q17,7)="Relance",Q17&" ","")&IF(K17="En retard","· Prévenir du retard de livraison","")))) | S17: =IF(B17="","",IF(LEFT(Q17,9)="Relance 3","Bonjour "&D17&", nous revenons vers vous au sujet de la commande "&A17&" du "&TEXT(B17,"dd/mm/yyyy")&" : "&SUBSTITUTE(TEXT(O17,"#,##0"),","," ")&" FCFA restent à régler depuis le "&TEXT(M17,"dd/mm/yyyy")&". Notre responsable souhaite vous appeler pour convenir ensemble d'une solution. Quel moment vous arrange cette semaine ? "&Paramètres!$B$11&", "&Paramètres!$B$12,IF(LEFT(Q17,7)="Relance","Bonjour "&D17&", sauf erreur de notre part, la commande "&A17&" du "&TEXT(B17,"dd/mm/yyyy")&" ("&E17&") présente un reste à payer de "&SUBSTITUTE(TEXT(O17,"#,##0"),","," ")&" FCFA, échu depuis le "&TEXT(M17,"dd/mm/yyyy")&". Pouvez-vous nous indiquer la date de règlement prévue ? Si le paiement est déjà parti, merci de nous envoyer la preuve et ne tenez pas compte de ce message. "&Paramètres!$B$11&", "&Paramètres!$B$12,IF(K17="En retard","Bonjour "&D17&", votre commande "&A17&" ("&E17&", "&F17&" pièces) prévue le "&TEXT(I17,"dd/mm/yyyy")&" a pris du retard. Nous vous confirmons la nouvelle date de livraison dans la journée. Toutes nos excuses pour ce contretemps. "&Paramètres!$B$11&", "&Paramètres!$B$12,""))))
D18: =IF(C18="","",IFERROR(VLOOKUP(C18,Revendeurs!$A:$B,2,FALSE),"Code inconnu")) | H18: =IF(OR(F18="",G18=""),"",F18*G18) | K18: =IF(B18="","",IF(J18<>"","Livrée",IF(I18="","À planifier",IF(Paramètres!$B$4>I18+Paramètres!$B$8,"En retard","En cours")))) | L18: =IF(K18="En retard",Paramètres!$B$4-I18,"") | M18: =IF(OR(B18="",J18=""),"",J18+IFERROR(IF(VLOOKUP(C18,Revendeurs!$A:$G,7,FALSE)="",Paramètres!$B$9,VLOOKUP(C18,Revendeurs!$A:$G,7,FALSE)),Paramètres!$B$9)) | O18: =IF(H18="","",H18-N18) | P18: =IF(OR(M18="",O18=""),"",IF(O18<=0,0,MAX(0,Paramètres!$B$4-M18))) | Q18: =IF(H18="","",IF(O18<=0,"Payée",IF(M18="","Pas encore livrée",IF(P18=0,"Non échue",IF(P18>=Paramètres!$B$7,"Relance 3 : appel direction",IF(P18>=Paramètres!$B$6,"Relance 2",IF(P18>=Paramètres!$B$5,"Relance 1","Échue, relance à venir"))))))) | R18: =IF(B18="","",IF(U18=Paramètres!$B$4,"Relancé aujourd'hui",TRIM(IF(LEFT(Q18,7)="Relance",Q18&" ","")&IF(K18="En retard","· Prévenir du retard de livraison","")))) | S18: =IF(B18="","",IF(LEFT(Q18,9)="Relance 3","Bonjour "&D18&", nous revenons vers vous au sujet de la commande "&A18&" du "&TEXT(B18,"dd/mm/yyyy")&" : "&SUBSTITUTE(TEXT(O18,"#,##0"),","," ")&" FCFA restent à régler depuis le "&TEXT(M18,"dd/mm/yyyy")&". Notre responsable souhaite vous appeler pour convenir ensemble d'une solution. Quel moment vous arrange cette semaine ? "&Paramètres!$B$11&", "&Paramètres!$B$12,IF(LEFT(Q18,7)="Relance","Bonjour "&D18&", sauf erreur de notre part, la commande "&A18&" du "&TEXT(B18,"dd/mm/yyyy")&" ("&E18&") présente un reste à payer de "&SUBSTITUTE(TEXT(O18,"#,##0"),","," ")&" FCFA, échu depuis le "&TEXT(M18,"dd/mm/yyyy")&". Pouvez-vous nous indiquer la date de règlement prévue ? Si le paiement est déjà parti, merci de nous envoyer la preuve et ne tenez pas compte de ce message. "&Paramètres!$B$11&", "&Paramètres!$B$12,IF(K18="En retard","Bonjour "&D18&", votre commande "&A18&" ("&E18&", "&F18&" pièces) prévue le "&TEXT(I18,"dd/mm/yyyy")&" a pris du retard. Nous vous confirmons la nouvelle date de livraison dans la journée. Toutes nos excuses pour ce contretemps. "&Paramètres!$B$11&", "&Paramètres!$B$12,""))))
D19: =IF(C19="","",IFERROR(VLOOKUP(C19,Revendeurs!$A:$B,2,FALSE),"Code inconnu")) | H19: =IF(OR(F19="",G19=""),"",F19*G19) | K19: =IF(B19="","",IF(J19<>"","Livrée",IF(I19="","À planifier",IF(Paramètres!$B$4>I19+Paramètres!$B$8,"En retard","En cours")))) | L19: =IF(K19="En retard",Paramètres!$B$4-I19,"") | M19: =IF(OR(B19="",J19=""),"",J19+IFERROR(IF(VLOOKUP(C19,Revendeurs!$A:$G,7,FALSE)="",Paramètres!$B$9,VLOOKUP(C19,Revendeurs!$A:$G,7,FALSE)),Paramètres!$B$9)) | O19: =IF(H19="","",H19-N19) | P19: =IF(OR(M19="",O19=""),"",IF(O19<=0,0,MAX(0,Paramètres!$B$4-M19))) | Q19: =IF(H19="","",IF(O19<=0,"Payée",IF(M19="","Pas encore livrée",IF(P19=0,"Non échue",IF(P19>=Paramètres!$B$7,"Relance 3 : appel direction",IF(P19>=Paramètres!$B$6,"Relance 2",IF(P19>=Paramètres!$B$5,"Relance 1","Échue, relance à venir"))))))) | R19: =IF(B19="","",IF(U19=Paramètres!$B$4,"Relancé aujourd'hui",TRIM(IF(LEFT(Q19,7)="Relance",Q19&" ","")&IF(K19="En retard","· Prévenir du retard de livraison","")))) | S19: =IF(B19="","",IF(LEFT(Q19,9)="Relance 3","Bonjour "&D19&", nous revenons vers vous au sujet de la commande "&A19&" du "&TEXT(B19,"dd/mm/yyyy")&" : "&SUBSTITUTE(TEXT(O19,"#,##0"),","," ")&" FCFA restent à régler depuis le "&TEXT(M19,"dd/mm/yyyy")&". Notre responsable souhaite vous appeler pour convenir ensemble d'une solution. Quel moment vous arrange cette semaine ? "&Paramètres!$B$11&", "&Paramètres!$B$12,IF(LEFT(Q19,7)="Relance","Bonjour "&D19&", sauf erreur de notre part, la commande "&A19&" du "&TEXT(B19,"dd/mm/yyyy")&" ("&E19&") présente un reste à payer de "&SUBSTITUTE(TEXT(O19,"#,##0"),","," ")&" FCFA, échu depuis le "&TEXT(M19,"dd/mm/yyyy")&". Pouvez-vous nous indiquer la date de règlement prévue ? Si le paiement est déjà parti, merci de nous envoyer la preuve et ne tenez pas compte de ce message. "&Paramètres!$B$11&", "&Paramètres!$B$12,IF(K19="En retard","Bonjour "&D19&", votre commande "&A19&" ("&E19&", "&F19&" pièces) prévue le "&TEXT(I19,"dd/mm/yyyy")&" a pris du retard. Nous vous confirmons la nouvelle date de livraison dans la journée. Toutes nos excuses pour ce contretemps. "&Paramètres!$B$11&", "&Paramètres!$B$12,""))))
D20: =IF(C20="","",IFERROR(VLOOKUP(C20,Revendeurs!$A:$B,2,FALSE),"Code inconnu")) | H20: =IF(OR(F20="",G20=""),"",F20*G20) | K20: =IF(B20="","",IF(J20<>"","Livrée",IF(I20="","À planifier",IF(Paramètres!$B$4>I20+Paramètres!$B$8,"En retard","En cours")))) | L20: =IF(K20="En retard",Paramètres!$B$4-I20,"") | M20: =IF(OR(B20="",J20=""),"",J20+IFERROR(IF(VLOOKUP(C20,Revendeurs!$A:$G,7,FALSE)="",Paramètres!$B$9,VLOOKUP(C20,Revendeurs!$A:$G,7,FALSE)),Paramètres!$B$9)) | O20: =IF(H20="","",H20-N20) | P20: =IF(OR(M20="",O20=""),"",IF(O20<=0,0,MAX(0,Paramètres!$B$4-M20))) | Q20: =IF(H20="","",IF(O20<=0,"Payée",IF(M20="","Pas encore livrée",IF(P20=0,"Non échue",IF(P20>=Paramètres!$B$7,"Relance 3 : appel direction",IF(P20>=Paramètres!$B$6,"Relance 2",IF(P20>=Paramètres!$B$5,"Relance 1","Échue, relance à venir"))))))) | R20: =IF(B20="","",IF(U20=Paramètres!$B$4,"Relancé aujourd'hui",TRIM(IF(LEFT(Q20,7)="Relance",Q20&" ","")&IF(K20="En retard","· Prévenir du retard de livraison","")))) | S20: =IF(B20="","",IF(LEFT(Q20,9)="Relance 3","Bonjour "&D20&", nous revenons vers vous au sujet de la commande "&A20&" du "&TEXT(B20,"dd/mm/yyyy")&" : "&SUBSTITUTE(TEXT(O20,"#,##0"),","," ")&" FCFA restent à régler depuis le "&TEXT(M20,"dd/mm/yyyy")&". Notre responsable souhaite vous appeler pour convenir ensemble d'une solution. Quel moment vous arrange cette semaine ? "&Paramètres!$B$11&", "&Paramètres!$B$12,IF(LEFT(Q20,7)="Relance","Bonjour "&D20&", sauf erreur de notre part, la commande "&A20&" du "&TEXT(B20,"dd/mm/yyyy")&" ("&E20&") présente un reste à payer de "&SUBSTITUTE(TEXT(O20,"#,##0"),","," ")&" FCFA, échu depuis le "&TEXT(M20,"dd/mm/yyyy")&". Pouvez-vous nous indiquer la date de règlement prévue ? Si le paiement est déjà parti, merci de nous envoyer la preuve et ne tenez pas compte de ce message. "&Paramètres!$B$11&", "&Paramètres!$B$12,IF(K20="En retard","Bonjour "&D20&", votre commande "&A20&" ("&E20&", "&F20&" pièces) prévue le "&TEXT(I20,"dd/mm/yyyy")&" a pris du retard. Nous vous confirmons la nouvelle date de livraison dans la journée. Toutes nos excuses pour ce contretemps. "&Paramètres!$B$11&", "&Paramètres!$B$12,""))))
D21: =IF(C21="","",IFERROR(VLOOKUP(C21,Revendeurs!$A:$B,2,FALSE),"Code inconnu")) | H21: =IF(OR(F21="",G21=""),"",F21*G21) | K21: =IF(B21="","",IF(J21<>"","Livrée",IF(I21="","À planifier",IF(Paramètres!$B$4>I21+Paramètres!$B$8,"En retard","En cours")))) | L21: =IF(K21="En retard",Paramètres!$B$4-I21,"") | M21: =IF(OR(B21="",J21=""),"",J21+IFERROR(IF(VLOOKUP(C21,Revendeurs!$A:$G,7,FALSE)="",Paramètres!$B$9,VLOOKUP(C21,Revendeurs!$A:$G,7,FALSE)),Paramètres!$B$9)) | O21: =IF(H21="","",H21-N21) | P21: =IF(OR(M21="",O21=""),"",IF(O21<=0,0,MAX(0,Paramètres!$B$4-M21))) | Q21: =IF(H21="","",IF(O21<=0,"Payée",IF(M21="","Pas encore livrée",IF(P21=0,"Non échue",IF(P21>=Paramètres!$B$7,"Relance 3 : appel direction",IF(P21>=Paramètres!$B$6,"Relance 2",IF(P21>=Paramètres!$B$5,"Relance 1","Échue, relance à venir"))))))) | R21: =IF(B21="","",IF(U21=Paramètres!$B$4,"Relancé aujourd'hui",TRIM(IF(LEFT(Q21,7)="Relance",Q21&" ","")&IF(K21="En retard","· Prévenir du retard de livraison","")))) | S21: =IF(B21="","",IF(LEFT(Q21,9)="Relance 3","Bonjour "&D21&", nous revenons vers vous au sujet de la commande "&A21&" du "&TEXT(B21,"dd/mm/yyyy")&" : "&SUBSTITUTE(TEXT(O21,"#,##0"),","," ")&" FCFA restent à régler depuis le "&TEXT(M21,"dd/mm/yyyy")&". Notre responsable souhaite vous appeler pour convenir ensemble d'une solution. Quel moment vous arrange cette semaine ? "&Paramètres!$B$11&", "&Paramètres!$B$12,IF(LEFT(Q21,7)="Relance","Bonjour "&D21&", sauf erreur de notre part, la commande "&A21&" du "&TEXT(B21,"dd/mm/yyyy")&" ("&E21&") présente un reste à payer de "&SUBSTITUTE(TEXT(O21,"#,##0"),","," ")&" FCFA, échu depuis le "&TEXT(M21,"dd/mm/yyyy")&". Pouvez-vous nous indiquer la date de règlement prévue ? Si le paiement est déjà parti, merci de nous envoyer la preuve et ne tenez pas compte de ce message. "&Paramètres!$B$11&", "&Paramètres!$B$12,IF(K21="En retard","Bonjour "&D21&", votre commande "&A21&" ("&E21&", "&F21&" pièces) prévue le "&TEXT(I21,"dd/mm/yyyy")&" a pris du retard. Nous vous confirmons la nouvelle date de livraison dans la journée. Toutes nos excuses pour ce contretemps. "&Paramètres!$B$11&", "&Paramètres!$B$12,""))))
D22: =IF(C22="","",IFERROR(VLOOKUP(C22,Revendeurs!$A:$B,2,FALSE),"Code inconnu")) | H22: =IF(OR(F22="",G22=""),"",F22*G22) | K22: =IF(B22="","",IF(J22<>"","Livrée",IF(I22="","À planifier",IF(Paramètres!$B$4>I22+Paramètres!$B$8,"En retard","En cours")))) | L22: =IF(K22="En retard",Paramètres!$B$4-I22,"") | M22: =IF(OR(B22="",J22=""),"",J22+IFERROR(IF(VLOOKUP(C22,Revendeurs!$A:$G,7,FALSE)="",Paramètres!$B$9,VLOOKUP(C22,Revendeurs!$A:$G,7,FALSE)),Paramètres!$B$9)) | O22: =IF(H22="","",H22-N22) | P22: =IF(OR(M22="",O22=""),"",IF(O22<=0,0,MAX(0,Paramètres!$B$4-M22))) | Q22: =IF(H22="","",IF(O22<=0,"Payée",IF(M22="","Pas encore livrée",IF(P22=0,"Non échue",IF(P22>=Paramètres!$B$7,"Relance 3 : appel direction",IF(P22>=Paramètres!$B$6,"Relance 2",IF(P22>=Paramètres!$B$5,"Relance 1","Échue, relance à venir"))))))) | R22: =IF(B22="","",IF(U22=Paramètres!$B$4,"Relancé aujourd'hui",TRIM(IF(LEFT(Q22,7)="Relance",Q22&" ","")&IF(K22="En retard","· Prévenir du retard de livraison","")))) | S22: =IF(B22="","",IF(LEFT(Q22,9)="Relance 3","Bonjour "&D22&", nous revenons vers vous au sujet de la commande "&A22&" du "&TEXT(B22,"dd/mm/yyyy")&" : "&SUBSTITUTE(TEXT(O22,"#,##0"),","," ")&" FCFA restent à régler depuis le "&TEXT(M22,"dd/mm/yyyy")&". Notre responsable souhaite vous appeler pour convenir ensemble d'une solution. Quel moment vous arrange cette semaine ? "&Paramètres!$B$11&", "&Paramètres!$B$12,IF(LEFT(Q22,7)="Relance","Bonjour "&D22&", sauf erreur de notre part, la commande "&A22&" du "&TEXT(B22,"dd/mm/yyyy")&" ("&E22&") présente un reste à payer de "&SUBSTITUTE(TEXT(O22,"#,##0"),","," ")&" FCFA, échu depuis le "&TEXT(M22,"dd/mm/yyyy")&". Pouvez-vous nous indiquer la date de règlement prévue ? Si le paiement est déjà parti, merci de nous envoyer la preuve et ne tenez pas compte de ce message. "&Paramètres!$B$11&", "&Paramètres!$B$12,IF(K22="En retard","Bonjour "&D22&", votre commande "&A22&" ("&E22&", "&F22&" pièces) prévue le "&TEXT(I22,"dd/mm/yyyy")&" a pris du retard. Nous vous confirmons la nouvelle date de livraison dans la journée. Toutes nos excuses pour ce contretemps. "&Paramètres!$B$11&", "&Paramètres!$B$12,""))))
